Workbook

Sheet DUTY_2025
A1: HS | C1: NORM/SG | D1: SCL | E1: Current Rate/kg | F1: ICL/SLSI | G1: SCL Price | H1: Normal Price | I1: CIF Based | J1: DUTY | K1: CIF Value | L1: Net Weight | M1: MRP | N1: Unit | O1: Invoice Percent | P1: Preferential Duty | Q1: Gen Duty | R1: VAT | S1: PAL_GEN | T1: PAL_SG | U1: CESS_GEN | V1: CESS_SG | W1: EXCISE | X1: SSCL | Y1: Preferential Duty | Z1: Gen Duty | AA1: VAT | AB1: PAL_GEN | AC1: PAL_SG | AD1: CESS_GEN | AE1: CESS_SG | AF1: EXCISE | AG1: SSCL | AH1: Preferential Duty | AI1: Gen Duty | AJ1: VAT | AK1: PAL_GEN | AL1: PAL_SG | AM1: CESS_GEN | AN1: CESS_SG | AO1: EXCISE | AP1: SSCL | AQ1: Preferential Duty | AR1: Gen Duty | AS1: VAT | AT1: PAL_GEN | AU1: PAL_SG | AV1: CESS_GEN | AW1: CESS_SG | AX1: EXCISE | AY1: SSCL
A2: 04059000 | B2: GHEE | C2: NORM | D2: SCL | E2: =IF(D2="SCL",G2,H2) -> 2000 | G2: 2000 | H2: =ROUND(I2,0) -> 1933 | I2: =IF(AND(L2<>"",L2<>0),ROUND(J2/L2,0),0) -> 1933 | J2: =IF(C2="SG",ROUND((P2+Q2+R2+T2+V2+W2+X2),0),ROUND((P2+Q2+R2+S2+U2+W2+X2),0)) -> 730800 | K2: =SUMIF(ProductList!$F$4:$F$493,A2,ProductList!$BA$4:$BA$493) -> 1119892 | L2: =SUMIF(ProductList!$F$4:$F$493,A2,ProductList!$V$4:$V$493) -> 378 | M2: =SUMIF(ProductList!$F$4:$F$493,A2,ProductList!$K$4:$K$493) -> 0 | N2: KG | O2: =IF(D2="SCL",100,AZ2) -> 100 | P2: =IF((K2*Y2)>(L2*AH2),(K2*Y2),(L2*AH2)) -> 0 | Q2: =IF((K2*Z2)>(L2*AI2),(K2*Z2),(L2*AI2)) -> 264600 | R2: =IF(C2="SG", IF(((K2*1.1+P2+Q2+T2+V2)*AA2)>(L2*AJ2), (K2*1.1+P2+Q2+T2+V2)*AA2, L2*AJ2), IF(((K2*1.1+P2+Q2+S2+U2)*AA2)>(L2*AJ2), (K2*1.1+P2+Q2+S2+U2)*AA2, L2*AJ2) ) -> 293180.62 | S2: =IF((K2*AB2)>(L2*AK2),(K2*AB2),(L2*AK2)) -> 0 | T2: =IF((K2*AC2)>(L2*AL2),(K2*AC2),(L2*AL2)) -> 0 | U2: =IF((K2*AD2)>(L2*AM2),(K2*AD2),(L2*AM2)) -> 132300 | V2: =IF((K2*AE2)>(L2*AN2),(K2*AE2),(L2*AN2)) -> 0 | W2: =IF((K2*AF2)>(L2*AO2),(K2*AF2),(L2*AO2)) -> 0 | X2: =IF((((K2)*1.1+P2+Q2+S2+T2+U2+V2)*AG2)>(L2*AP2),(((K2)*1.1+P2+Q2+S2+T2+U2+V2)*AG2),(L2*AP2)) -> 40719.53 | Z2: 0.2 | AA2: 0.18 | AD2: 0.1 | AG2: 0.025 | AI2: 700 | AM2: 350 | AZ2: 80
A3: 04090000 | B3: HONEY | D3: NORM | E3: =IF(D3="SCL",G3,H3) -> 0 | H3: =ROUND(I3,0) -> 0 | I3: =IF(AND(L3<>"",L3<>0),ROUND(J3/L3,0),0) -> 0 | J3: =IF(C3="SG",ROUND((P3+Q3+R3+T3+V3+W3+X3),0),ROUND((P3+Q3+R3+S3+U3+W3+X3),0)) -> 0 | K3: =SUMIF(ProductList!$F$4:$F$493,A3,ProductList!$BA$4:$BA$493) -> 0 | L3: =SUMIF(ProductList!$F$4:$F$493,A3,ProductList!$V$4:$V$493) -> 0 | M3: =SUMIF(ProductList!$F$4:$F$493,A3,ProductList!$K$4:$K$493) -> 0 | N3: KG | O3: =IF(D3="SCL",100,AZ3) -> 80 | P3: =IF((K3*Y3)>(L3*AH3),(K3*Y3),(L3*AH3)) -> 0 | Q3: =IF((K3*Z3)>(L3*AI3),(K3*Z3),(L3*AI3)) -> 0 | R3: =IF(C3="SG", IF(((K3*1.1+P3+Q3+T3+V3)*AA3)>(L3*AJ3), (K3*1.1+P3+Q3+T3+V3)*AA3, L3*AJ3), IF(((K3*1.1+P3+Q3+S3+U3)*AA3)>(L3*AJ3), (K3*1.1+P3+Q3+S3+U3)*AA3, L3*AJ3) ) -> 0 | S3: =IF((K3*AB3)>(L3*AK3),(K3*AB3),(L3*AK3)) -> 0 | T3: =IF((K3*AC3)>(L3*AL3),(K3*AC3),(L3*AL3)) -> 0 | U3: =IF((K3*AD3)>(L3*AM3),(K3*AD3),(L3*AM3)) -> 0 | V3: =IF((K3*AE3)>(L3*AN3),(K3*AE3),(L3*AN3)) -> 0 | W3: =IF((K3*AF3)>(L3*AO3),(K3*AF3),(L3*AO3)) -> 0 | X3: =IF((((K3)*1.1+P3+Q3+S3+T3+U3+V3)*AG3)>(L3*AP3),(((K3)*1.1+P3+Q3+S3+T3+U3+V3)*AG3),(L3*AP3)) -> 0 | Z3: 0.2 | AA3: 0.18 | AB3: 0.1 | AD3: 0.1 | AG3: 0.025 | AZ3: =AZ2 -> 80
A4: 07133119 | B4: GREEN GRAM - OTHER | D4: SCL | E4: =IF(D4="SCL",G4,H4) -> 300 | G4: 300 | H4: =ROUND(I4,0) -> 0 | I4: =IF(AND(L4<>"",L4<>0),ROUND(J4/L4,0),0) -> 0 | J4: =IF(C4="SG",ROUND((P4+Q4+R4+T4+V4+W4+X4),0),ROUND((P4+Q4+R4+S4+U4+W4+X4),0)) -> 0 | K4: =SUMIF(ProductList!$F$4:$F$493,A4,ProductList!$BA$4:$BA$493) -> 0 | L4: =SUMIF(ProductList!$F$4:$F$493,A4,ProductList!$V$4:$V$493) -> 0 | M4: =SUMIF(ProductList!$F$4:$F$493,A4,ProductList!$K$4:$K$493) -> 0 | N4: KG | O4: =IF(D4="SCL",100,AZ4) -> 100 | P4: =IF((K4*Y4)>(L4*AH4),(K4*Y4),(L4*AH4)) -> 0 | Q4: =IF((K4*Z4)>(L4*AI4),(K4*Z4),(L4*AI4)) -> 0 | R4: =IF(C4="SG", IF(((K4*1.1+P4+Q4+T4+V4)*AA4)>(L4*AJ4), (K4*1.1+P4+Q4+T4+V4)*AA4, L4*AJ4), IF(((K4*1.1+P4+Q4+S4+U4)*AA4)>(L4*AJ4), (K4*1.1+P4+Q4+S4+U4)*AA4, L4*AJ4) ) -> 0 | S4: =IF((K4*AB4)>(L4*AK4),(K4*AB4),(L4*AK4)) -> 0 | T4: =IF((K4*AC4)>(L4*AL4),(K4*AC4),(L4*AL4)) -> 0 | U4: =IF((K4*AD4)>(L4*AM4),(K4*AD4),(L4*AM4)) -> 0 | V4: =IF((K4*AE4)>(L4*AN4),(K4*AE4),(L4*AN4)) -> 0 | W4: =IF((K4*AF4)>(L4*AO4),(K4*AF4),(L4*AO4)) -> 0 | X4: =IF((((K4)*1.1+P4+Q4+S4+T4+U4+V4)*AG4)>(L4*AP4),(((K4)*1.1+P4+Q4+S4+T4+U4+V4)*AG4),(L4*AP4)) -> 0 | AZ4: =AZ3 -> 80
A5: 07133129 | B5: BLACK GRAM | D5: SCL | E5: =IF(D5="SCL",G5,H5) -> 300 | G5: 300 | H5: =ROUND(I5,0) -> 0 | I5: =IF(AND(L5<>"",L5<>0),ROUND(J5/L5,0),0) -> 0 | J5: =IF(C5="SG",ROUND((P5+Q5+R5+T5+V5+W5+X5),0),ROUND((P5+Q5+R5+S5+U5+W5+X5),0)) -> 0 | K5: =SUMIF(ProductList!$F$4:$F$493,A5,ProductList!$BA$4:$BA$493) -> 0 | L5: =SUMIF(ProductList!$F$4:$F$493,A5,ProductList!$V$4:$V$493) -> 0 | M5: =SUMIF(ProductList!$F$4:$F$493,A5,ProductList!$K$4:$K$493) -> 0 | N5: KG | O5: =IF(D5="SCL",100,AZ5) -> 100 | P5: =IF((K5*Y5)>(L5*AH5),(K5*Y5),(L5*AH5)) -> 0 | Q5: =IF((K5*Z5)>(L5*AI5),(K5*Z5),(L5*AI5)) -> 0 | R5: =IF(C5="SG", IF(((K5*1.1+P5+Q5+T5+V5)*AA5)>(L5*AJ5), (K5*1.1+P5+Q5+T5+V5)*AA5, L5*AJ5), IF(((K5*1.1+P5+Q5+S5+U5)*AA5)>(L5*AJ5), (K5*1.1+P5+Q5+S5+U5)*AA5, L5*AJ5) ) -> 0 | S5: =IF((K5*AB5)>(L5*AK5),(K5*AB5),(L5*AK5)) -> 0 | T5: =IF((K5*AC5)>(L5*AL5),(K5*AC5),(L5*AL5)) -> 0 | U5: =IF((K5*AD5)>(L5*AM5),(K5*AD5),(L5*AM5)) -> 0 | V5: =IF((K5*AE5)>(L5*AN5),(K5*AE5),(L5*AN5)) -> 0 | W5: =IF((K5*AF5)>(L5*AO5),(K5*AF5),(L5*AO5)) -> 0 | X5: =IF((((K5)*1.1+P5+Q5+S5+T5+U5+V5)*AG5)>(L5*AP5),(((K5)*1.1+P5+Q5+S5+T5+U5+V5)*AG5),(L5*AP5)) -> 0 | AZ5: =AZ4 -> 80
A6: 07133990 | B6: BEANS - OTHERS | E6: =IF(D6="SCL",G6,H6) -> 0 | H6: =ROUND(I6,0) -> 0 | I6: =IF(AND(L6<>"",L6<>0),ROUND(J6/L6,0),0) -> 0 | J6: =IF(C6="SG",ROUND((P6+Q6+R6+T6+V6+W6+X6),0),ROUND((P6+Q6+R6+S6+U6+W6+X6),0)) -> 0 | K6: =SUMIF(ProductList!$F$4:$F$493,A6,ProductList!$BA$4:$BA$493) -> 0 | L6: =SUMIF(ProductList!$F$4:$F$493,A6,ProductList!$V$4:$V$493) -> 0 | M6: =SUMIF(ProductList!$F$4:$F$493,A6,ProductList!$K$4:$K$493) -> 0 | N6: KG | O6: =IF(D6="SCL",100,AZ6) -> 80 | P6: =IF((K6*Y6)>(L6*AH6),(K6*Y6),(L6*AH6)) -> 0 | Q6: =IF((K6*Z6)>(L6*AI6),(K6*Z6),(L6*AI6)) -> 0 | R6: =IF(C6="SG", IF(((K6*1.1+P6+Q6+T6+V6)*AA6)>(L6*AJ6), (K6*1.1+P6+Q6+T6+V6)*AA6, L6*AJ6), IF(((K6*1.1+P6+Q6+S6+U6)*AA6)>(L6*AJ6), (K6*1.1+P6+Q6+S6+U6)*AA6, L6*AJ6) ) -> 0 | S6: =IF((K6*AB6)>(L6*AK6),(K6*AB6),(L6*AK6)) -> 0 | T6: =IF((K6*AC6)>(L6*AL6),(K6*AC6),(L6*AL6)) -> 0 | U6: =IF((K6*AD6)>(L6*AM6),(K6*AD6),(L6*AM6)) -> 0 | V6: =IF((K6*AE6)>(L6*AN6),(K6*AE6),(L6*AN6)) -> 0 | W6: =IF((K6*AF6)>(L6*AO6),(K6*AF6),(L6*AO6)) -> 0 | X6: =IF((((K6)*1.1+P6+Q6+S6+T6+U6+V6)*AG6)>(L6*AP6),(((K6)*1.1+P6+Q6+S6+T6+U6+V6)*AG6),(L6*AP6)) -> 0 | Z6: 0.2 | AA6: 0.18 | AB6: 0.1 | AD6: 0.1 | AG6: 0.025 | AZ6: =AZ5 -> 80
A7: 07136010 | B7: TOOR DHAL | D7: NORM | E7: =IF(D7="SCL",G7,H7) -> 0 | H7: =ROUND(I7,0) -> 0 | I7: =IF(AND(L7<>"",L7<>0),ROUND(J7/L7,0),0) -> 0 | J7: =IF(C7="SG",ROUND((P7+Q7+R7+T7+V7+W7+X7),0),ROUND((P7+Q7+R7+S7+U7+W7+X7),0)) -> 0 | K7: =SUMIF(ProductList!$F$4:$F$493,A7,ProductList!$BA$4:$BA$493) -> 0 | L7: =SUMIF(ProductList!$F$4:$F$493,A7,ProductList!$V$4:$V$493) -> 0 | M7: =SUMIF(ProductList!$F$4:$F$493,A7,ProductList!$K$4:$K$493) -> 0 | N7: KG | O7: =IF(D7="SCL",100,AZ7) -> 80 | P7: =IF((K7*Y7)>(L7*AH7),(K7*Y7),(L7*AH7)) -> 0 | Q7: =IF((K7*Z7)>(L7*AI7),(K7*Z7),(L7*AI7)) -> 0 | R7: =IF(C7="SG", IF(((K7*1.1+P7+Q7+T7+V7)*AA7)>(L7*AJ7), (K7*1.1+P7+Q7+T7+V7)*AA7, L7*AJ7), IF(((K7*1.1+P7+Q7+S7+U7)*AA7)>(L7*AJ7), (K7*1.1+P7+Q7+S7+U7)*AA7, L7*AJ7) ) -> 0 | S7: =IF((K7*AB7)>(L7*AK7),(K7*AB7),(L7*AK7)) -> 0 | T7: =IF((K7*AC7)>(L7*AL7),(K7*AC7),(L7*AL7)) -> 0 | U7: =IF((K7*AD7)>(L7*AM7),(K7*AD7),(L7*AM7)) -> 0 | V7: =IF((K7*AE7)>(L7*AN7),(K7*AE7),(L7*AN7)) -> 0 | W7: =IF((K7*AF7)>(L7*AO7),(K7*AF7),(L7*AO7)) -> 0 | X7: =IF((((K7)*1.1+P7+Q7+S7+T7+U7+V7)*AG7)>(L7*AP7),(((K7)*1.1+P7+Q7+S7+T7+U7+V7)*AG7),(L7*AP7)) -> 0 | AA7: 0.18 | AB7: 0.1 | AC7: 0.06 | AG7: 0.025 | AI7: 45 | AZ7: =AZ6 -> 80
A8: 09019000 | B8: COFFEE ROASTED | D8: NORM | E8: =IF(D8="SCL",G8,H8) -> 0 | H8: =ROUND(I8,0) -> 0 | I8: =IF(AND(L8<>"",L8<>0),ROUND(J8/L8,0),0) -> 0 | J8: =IF(C8="SG",ROUND((P8+Q8+R8+T8+V8+W8+X8),0),ROUND((P8+Q8+R8+S8+U8+W8+X8),0)) -> 0 | K8: =SUMIF(ProductList!$F$4:$F$493,A8,ProductList!$BA$4:$BA$493) -> 0 | L8: =SUMIF(ProductList!$F$4:$F$493,A8,ProductList!$V$4:$V$493) -> 0 | M8: =SUMIF(ProductList!$F$4:$F$493,A8,ProductList!$K$4:$K$493) -> 0 | N8: KG | O8: =IF(D8="SCL",100,AZ8) -> 80 | P8: =IF((K8*Y8)>(L8*AH8),(K8*Y8),(L8*AH8)) -> 0 | Q8: =IF((K8*Z8)>(L8*AI8),(K8*Z8),(L8*AI8)) -> 0 | R8: =IF(C8="SG", IF(((K8*1.1+P8+Q8+T8+V8)*AA8)>(L8*AJ8), (K8*1.1+P8+Q8+T8+V8)*AA8, L8*AJ8), IF(((K8*1.1+P8+Q8+S8+U8)*AA8)>(L8*AJ8), (K8*1.1+P8+Q8+S8+U8)*AA8, L8*AJ8) ) -> 0 | S8: =IF((K8*AB8)>(L8*AK8),(K8*AB8),(L8*AK8)) -> 0 | T8: =IF((K8*AC8)>(L8*AL8),(K8*AC8),(L8*AL8)) -> 0 | U8: =IF((K8*AD8)>(L8*AM8),(K8*AD8),(L8*AM8)) -> 0 | V8: =IF((K8*AE8)>(L8*AN8),(K8*AE8),(L8*AN8)) -> 0 | W8: =IF((K8*AF8)>(L8*AO8),(K8*AF8),(L8*AO8)) -> 0 | X8: =IF((((K8)*1.1+P8+Q8+S8+T8+U8+V8)*AG8)>(L8*AP8),(((K8)*1.1+P8+Q8+S8+T8+U8+V8)*AG8),(L8*AP8)) -> 0 | Z8: 0.2 | AA8: 0.18 | AB8: 0.1 | AD8: 0.25 | AG8: 0.025 | AZ8: =AZ7 -> 80
A9: 09023021 | B9: FLAVOURED TEA | D9: NORM | E9: =IF(D9="SCL",G9,H9) -> 0 | H9: =ROUND(I9,0) -> 0 | I9: =IF(AND(L9<>"",L9<>0),ROUND(J9/L9,0),0) -> 0 | J9: =IF(C9="SG",ROUND((P9+Q9+R9+T9+V9+W9+X9),0),ROUND((P9+Q9+R9+S9+U9+W9+X9),0)) -> 0 | K9: =SUMIF(ProductList!$F$4:$F$493,A9,ProductList!$BA$4:$BA$493) -> 0 | L9: =SUMIF(ProductList!$F$4:$F$493,A9,ProductList!$V$4:$V$493) -> 0 | M9: =SUMIF(ProductList!$F$4:$F$493,A9,ProductList!$K$4:$K$493) -> 0 | N9: KG | O9: =IF(D9="SCL",100,AZ9) -> 80 | P9: =IF((K9*Y9)>(L9*AH9),(K9*Y9),(L9*AH9)) -> 0 | Q9: =IF((K9*Z9)>(L9*AI9),(K9*Z9),(L9*AI9)) -> 0 | R9: =IF(C9="SG", IF(((K9*1.1+P9+Q9+T9+V9)*AA9)>(L9*AJ9), (K9*1.1+P9+Q9+T9+V9)*AA9, L9*AJ9), IF(((K9*1.1+P9+Q9+S9+U9)*AA9)>(L9*AJ9), (K9*1.1+P9+Q9+S9+U9)*AA9, L9*AJ9) ) -> 0 | S9: =IF((K9*AB9)>(L9*AK9),(K9*AB9),(L9*AK9)) -> 0 | T9: =IF((K9*AC9)>(L9*AL9),(K9*AC9),(L9*AL9)) -> 0 | U9: =IF((K9*AD9)>(L9*AM9),(K9*AD9),(L9*AM9)) -> 0 | V9: =IF((K9*AE9)>(L9*AN9),(K9*AE9),(L9*AN9)) -> 0 | W9: =IF((K9*AF9)>(L9*AO9),(K9*AF9),(L9*AO9)) -> 0 | X9: =IF((((K9)*1.1+P9+Q9+S9+T9+U9+V9)*AG9)>(L9*AP9),(((K9)*1.1+P9+Q9+S9+T9+U9+V9)*AG9),(L9*AP9)) -> 0 | Z9: 0.2 | AA9: 0.18 | AB9: 0 | AC9: 0 | AD9: 0.1 | AG9: 0.025 | AZ9: =AZ8 -> 80
A10: 09042190 | B10: CHILLIES- OTHER | D10: NORM | E10: =IF(D10="SCL",G10,H10) -> 705 | H10: =ROUND(I10,0) -> 705 | I10: =IF(AND(L10<>"",L10<>0),ROUND(J10/L10,0),0) -> 705 | J10: =IF(C10="SG",ROUND((P10+Q10+R10+T10+V10+W10+X10),0),ROUND((P10+Q10+R10+S10+U10+W10+X10),0)) -> 754592 | K10: =SUMIF(ProductList!$F$4:$F$493,A10,ProductList!$BA$4:$BA$493) -> 849526.4 | L10: =SUMIF(ProductList!$F$4:$F$493,A10,ProductList!$V$4:$V$493) -> 1070 | M10: =SUMIF(ProductList!$F$4:$F$493,A10,ProductList!$K$4:$K$493) -> 0 | N10: KG | O10: =IF(D10="SCL",100,AZ10) -> 80 | P10: =IF((K10*Y10)>(L10*AH10),(K10*Y10),(L10*AH10)) -> 0 | Q10: =IF((K10*Z10)>(L10*AI10),(K10*Z10),(L10*AI10)) -> 169905.28 | R10: =IF(C10="SG", IF(((K10*1.1+P10+Q10+T10+V10)*AA10)>(L10*AJ10), (K10*1.1+P10+Q10+T10+V10)*AA10, L10*AJ10), IF(((K10*1.1+P10+Q10+S10+U10)*AA10)>(L10*AJ10), (K10*1.1+P10+Q10+S10+U10)*AA10, L10*AJ10) ) -> 252309.34 | S10: =IF((K10*AB10)>(L10*AK10),(K10*AB10),(L10*AK10)) -> 84952.64 | T10: =IF((K10*AC10)>(L10*AL10),(K10*AC10),(L10*AL10)) -> 0 | U10: =IF((K10*AD10)>(L10*AM10),(K10*AD10),(L10*AM10)) -> 212381.6 | V10: =IF((K10*AE10)>(L10*AN10),(K10*AE10),(L10*AN10)) -> 0 | W10: =IF((K10*AF10)>(L10*AO10),(K10*AF10),(L10*AO10)) -> 0 | X10: =IF((((K10)*1.1+P10+Q10+S10+T10+U10+V10)*AG10)>(L10*AP10),(((K10)*1.1+P10+Q10+S10+T10+U10+V10)*AG10),(L10*AP10)) -> 35042.964 | Z10: 0.2 | AA10: 0.18 | AB10: 0.1 | AD10: 0.25 | AG10: 0.025 | AZ10: =AZ9 -> 80
A11: 09042210 | B11: CHILLIES | D11: SCL | E11: =IF(D11="SCL",G11,H11) -> 125 | F11: S | G11: 125 | H11: =ROUND(I11,0) -> 0 | I11: =IF(AND(L11<>"",L11<>0),ROUND(J11/L11,0),0) -> 0 | J11: =IF(C11="SG",ROUND((P11+Q11+R11+T11+V11+W11+X11),0),ROUND((P11+Q11+R11+S11+U11+W11+X11),0)) -> 0 | K11: =SUMIF(ProductList!$F$4:$F$493,A11,ProductList!$BA$4:$BA$493) -> 0 | L11: =SUMIF(ProductList!$F$4:$F$493,A11,ProductList!$V$4:$V$493) -> 0 | M11: =SUMIF(ProductList!$F$4:$F$493,A11,ProductList!$K$4:$K$493) -> 0 | N11: KG | O11: =IF(D11="SCL",100,AZ11) -> 100 | P11: =IF((K11*Y11)>(L11*AH11),(K11*Y11),(L11*AH11)) -> 0 | Q11: =IF((K11*Z11)>(L11*AI11),(K11*Z11),(L11*AI11)) -> 0 | R11: =IF(C11="SG", IF(((K11*1.1+P11+Q11+T11+V11)*AA11)>(L11*AJ11), (K11*1.1+P11+Q11+T11+V11)*AA11, L11*AJ11), IF(((K11*1.1+P11+Q11+S11+U11)*AA11)>(L11*AJ11), (K11*1.1+P11+Q11+S11+U11)*AA11, L11*AJ11) ) -> 0 | S11: =IF((K11*AB11)>(L11*AK11),(K11*AB11),(L11*AK11)) -> 0 | T11: =IF((K11*AC11)>(L11*AL11),(K11*AC11),(L11*AL11)) -> 0 | U11: =IF((K11*AD11)>(L11*AM11),(K11*AD11),(L11*AM11)) -> 0 | V11: =IF((K11*AE11)>(L11*AN11),(K11*AE11),(L11*AN11)) -> 0 | W11: =IF((K11*AF11)>(L11*AO11),(K11*AF11),(L11*AO11)) -> 0 | X11: =IF((((K11)*1.1+P11+Q11+S11+T11+U11+V11)*AG11)>(L11*AP11),(((K11)*1.1+P11+Q11+S11+T11+U11+V11)*AG11),(L11*AP11)) -> 0 | AZ11: =AZ10 -> 80
A12: 09083290 | B12: CARDAMOM | D12: SCL | E12: =IF(D12="SCL",G12,H12) -> 2900 | G12: 2900 | H12: =ROUND(I12,0) -> 0 | I12: =IF(AND(L12<>"",L12<>0),ROUND(J12/L12,0),0) -> 0 | J12: =IF(C12="SG",ROUND((P12+Q12+R12+T12+V12+W12+X12),0),ROUND((P12+Q12+R12+S12+U12+W12+X12),0)) -> 0 | K12: =SUMIF(ProductList!$F$4:$F$493,A12,ProductList!$BA$4:$BA$493) -> 0 | L12: =SUMIF(ProductList!$F$4:$F$493,A12,ProductList!$V$4:$V$493) -> 0 | M12: =SUMIF(ProductList!$F$4:$F$493,A12,ProductList!$K$4:$K$493) -> 0 | N12: KG | O12: =IF(D12="SCL",100,AZ12) -> 100 | P12: =IF((K12*Y12)>(L12*AH12),(K12*Y12),(L12*AH12)) -> 0 | Q12: =IF((K12*Z12)>(L12*AI12),(K12*Z12),(L12*AI12)) -> 0 | R12: =IF(C12="SG", IF(((K12*1.1+P12+Q12+T12+V12)*AA12)>(L12*AJ12), (K12*1.1+P12+Q12+T12+V12)*AA12, L12*AJ12), IF(((K12*1.1+P12+Q12+S12+U12)*AA12)>(L12*AJ12), (K12*1.1+P12+Q12+S12+U12)*AA12, L12*AJ12) ) -> 0 | S12: =IF((K12*AB12)>(L12*AK12),(K12*AB12),(L12*AK12)) -> 0 | T12: =IF((K12*AC12)>(L12*AL12),(K12*AC12),(L12*AL12)) -> 0 | U12: =IF((K12*AD12)>(L12*AM12),(K12*AD12),(L12*AM12)) -> 0 | V12: =IF((K12*AE12)>(L12*AN12),(K12*AE12),(L12*AN12)) -> 0 | W12: =IF((K12*AF12)>(L12*AO12),(K12*AF12),(L12*AO12)) -> 0 | X12: =IF((((K12)*1.1+P12+Q12+S12+T12+U12+V12)*AG12)>(L12*AP12),(((K12)*1.1+P12+Q12+S12+T12+U12+V12)*AG12),(L12*AP12)) -> 0 | AZ12: =AZ11 -> 80
A13: 09092200 | B13: DHANIYA POWDER | D13: SCL | E13: =IF(D13="SCL",G13,H13) -> 52 | F13: S | G13: 52 | H13: =ROUND(I13,0) -> 421 | I13: =IF(AND(L13<>"",L13<>0),ROUND(J13/L13,0),0) -> 421 | J13: =IF(C13="SG",ROUND((P13+Q13+R13+T13+V13+W13+X13),0),ROUND((P13+Q13+R13+S13+U13+W13+X13),0)) -> 614924 | K13: =SUMIF(ProductList!$F$4:$F$493,A13,ProductList!$BA$4:$BA$493) -> 1318166 | L13: =SUMIF(ProductList!$F$4:$F$493,A13,ProductList!$V$4:$V$493) -> 1460 | M13: =SUMIF(ProductList!$F$4:$F$493,A13,ProductList!$K$4:$K$493) -> 0 | N13: KG | O13: =IF(D13="SCL",100,AZ13) -> 100 | P13: =IF((K13*Y13)>(L13*AH13),(K13*Y13),(L13*AH13)) -> 0 | Q13: =IF((K13*Z13)>(L13*AI13),(K13*Z13),(L13*AI13)) -> 263633.2 | R13: =IF(C13="SG", IF(((K13*1.1+P13+Q13+T13+V13)*AA13)>(L13*AJ13), (K13*1.1+P13+Q13+T13+V13)*AA13, L13*AJ13), IF(((K13*1.1+P13+Q13+S13+U13)*AA13)>(L13*AJ13), (K13*1.1+P13+Q13+S13+U13)*AA13, L13*AJ13) ) -> 308450.84 | S13: =IF((K13*AB13)>(L13*AK13),(K13*AB13),(L13*AK13)) -> 0 | T13: =IF((K13*AC13)>(L13*AL13),(K13*AC13),(L13*AL13)) -> 0 | U13: =IF((K13*AD13)>(L13*AM13),(K13*AD13),(L13*AM13)) -> 0 | V13: =IF((K13*AE13)>(L13*AN13),(K13*AE13),(L13*AN13)) -> 0 | W13: =IF((K13*AF13)>(L13*AO13),(K13*AF13),(L13*AO13)) -> 0 | X13: =IF((((K13)*1.1+P13+Q13+S13+T13+U13+V13)*AG13)>(L13*AP13),(((K13)*1.1+P13+Q13+S13+T13+U13+V13)*AG13),(L13*AP13)) -> 42840.395 | Z13: 0.2 | AA13: 0.18 | AG13: 0.025 | AZ13: =AZ12 -> 80
A14: 09093190 | B14: BLACK CUMIN | D14: NORM | E14: =IF(D14="SCL",G14,H14) -> 0 | G14: 162 | H14: =ROUND(I14,0) -> 0 | I14: =IF(AND(L14<>"",L14<>0),ROUND(J14/L14,0),0) -> 0 | J14: =IF(C14="SG",ROUND((P14+Q14+R14+T14+V14+W14+X14),0),ROUND((P14+Q14+R14+S14+U14+W14+X14),0)) -> 0 | K14: =SUMIF(ProductList!$F$4:$F$493,A14,ProductList!$BA$4:$BA$493) -> 0 | L14: =SUMIF(ProductList!$F$4:$F$493,A14,ProductList!$V$4:$V$493) -> 0 | M14: =SUMIF(ProductList!$F$4:$F$493,A14,ProductList!$K$4:$K$493) -> 0 | N14: KG | O14: =IF(D14="SCL",100,AZ14) -> 80 | P14: =IF((K14*Y14)>(L14*AH14),(K14*Y14),(L14*AH14)) -> 0 | Q14: =IF((K14*Z14)>(L14*AI14),(K14*Z14),(L14*AI14)) -> 0 | R14: =IF(C14="SG", IF(((K14*1.1+P14+Q14+T14+V14)*AA14)>(L14*AJ14), (K14*1.1+P14+Q14+T14+V14)*AA14, L14*AJ14), IF(((K14*1.1+P14+Q14+S14+U14)*AA14)>(L14*AJ14), (K14*1.1+P14+Q14+S14+U14)*AA14, L14*AJ14) ) -> 0 | S14: =IF((K14*AB14)>(L14*AK14),(K14*AB14),(L14*AK14)) -> 0 | T14: =IF((K14*AC14)>(L14*AL14),(K14*AC14),(L14*AL14)) -> 0 | U14: =IF((K14*AD14)>(L14*AM14),(K14*AD14),(L14*AM14)) -> 0 | V14: =IF((K14*AE14)>(L14*AN14),(K14*AE14),(L14*AN14)) -> 0 | W14: =IF((K14*AF14)>(L14*AO14),(K14*AF14),(L14*AO14)) -> 0 | X14: =IF((((K14)*1.1+P14+Q14+S14+T14+U14+V14)*AG14)>(L14*AP14),(((K14)*1.1+P14+Q14+S14+T14+U14+V14)*AG14),(L14*AP14)) -> 0 | AZ14: =AZ13 -> 80
A15: 09103010 | B15: TURMERIC | E15: =IF(D15="SCL",G15,H15) -> 0 | F15: L | H15: =ROUND(I15,0) -> 0 | I15: =IF(AND(L15<>"",L15<>0),ROUND(J15/L15,0),0) -> 0 | J15: =IF(C15="SG",ROUND((P15+Q15+R15+T15+V15+W15+X15),0),ROUND((P15+Q15+R15+S15+U15+W15+X15),0)) -> 0 | K15: =SUMIF(ProductList!$F$4:$F$493,A15,ProductList!$BA$4:$BA$493) -> 0 | L15: =SUMIF(ProductList!$F$4:$F$493,A15,ProductList!$V$4:$V$493) -> 0 | M15: =SUMIF(ProductList!$F$4:$F$493,A15,ProductList!$K$4:$K$493) -> 0 | N15: KG | O15: =IF(D15="SCL",100,AZ15) -> 80 | P15: =IF((K15*Y15)>(L15*AH15),(K15*Y15),(L15*AH15)) -> 0 | Q15: =IF((K15*Z15)>(L15*AI15),(K15*Z15),(L15*AI15)) -> 0 | R15: =IF(C15="SG", IF(((K15*1.1+P15+Q15+T15+V15)*AA15)>(L15*AJ15), (K15*1.1+P15+Q15+T15+V15)*AA15, L15*AJ15), IF(((K15*1.1+P15+Q15+S15+U15)*AA15)>(L15*AJ15), (K15*1.1+P15+Q15+S15+U15)*AA15, L15*AJ15) ) -> 0 | S15: =IF((K15*AB15)>(L15*AK15),(K15*AB15),(L15*AK15)) -> 0 | T15: =IF((K15*AC15)>(L15*AL15),(K15*AC15),(L15*AL15)) -> 0 | U15: =IF((K15*AD15)>(L15*AM15),(K15*AD15),(L15*AM15)) -> 0 | V15: =IF((K15*AE15)>(L15*AN15),(K15*AE15),(L15*AN15)) -> 0 | W15: =IF((K15*AF15)>(L15*AO15),(K15*AF15),(L15*AO15)) -> 0 | X15: =IF((((K15)*1.1+P15+Q15+S15+T15+U15+V15)*AG15)>(L15*AP15),(((K15)*1.1+P15+Q15+S15+T15+U15+V15)*AG15),(L15*AP15)) -> 0 | AZ15: =AZ14 -> 80
A16: 09109190 | B16: ASSORTED MASALA | D16: NORM | E16: =IF(D16="SCL",G16,H16) -> 0 | H16: =ROUND(I16,0) -> 0 | I16: =IF(AND(L16<>"",L16<>0),ROUND(J16/L16,0),0) -> 0 | J16: =IF(C16="SG",ROUND((P16+Q16+R16+T16+V16+W16+X16),0),ROUND((P16+Q16+R16+S16+U16+W16+X16),0)) -> 0 | K16: =SUMIF(ProductList!$F$4:$F$493,A16,ProductList!$BA$4:$BA$493) -> 0 | L16: =SUMIF(ProductList!$F$4:$F$493,A16,ProductList!$V$4:$V$493) -> 0 | M16: =SUMIF(ProductList!$F$4:$F$493,A16,ProductList!$K$4:$K$493) -> 0 | N16: KG | O16: =IF(D16="SCL",100,AZ16) -> 80 | P16: =IF((K16*Y16)>(L16*AH16),(K16*Y16),(L16*AH16)) -> 0 | Q16: =IF((K16*Z16)>(L16*AI16),(K16*Z16),(L16*AI16)) -> 0 | R16: =IF(C16="SG", IF(((K16*1.1+P16+Q16+T16+V16)*AA16)>(L16*AJ16), (K16*1.1+P16+Q16+T16+V16)*AA16, L16*AJ16), IF(((K16*1.1+P16+Q16+S16+U16)*AA16)>(L16*AJ16), (K16*1.1+P16+Q16+S16+U16)*AA16, L16*AJ16) ) -> 0 | S16: =IF((K16*AB16)>(L16*AK16),(K16*AB16),(L16*AK16)) -> 0 | T16: =IF((K16*AC16)>(L16*AL16),(K16*AC16),(L16*AL16)) -> 0 | U16: =IF((K16*AD16)>(L16*AM16),(K16*AD16),(L16*AM16)) -> 0 | V16: =IF((K16*AE16)>(L16*AN16),(K16*AE16),(L16*AN16)) -> 0 | W16: =IF((K16*AF16)>(L16*AO16),(K16*AF16),(L16*AO16)) -> 0 | X16: =IF((((K16)*1.1+P16+Q16+S16+T16+U16+V16)*AG16)>(L16*AP16),(((K16)*1.1+P16+Q16+S16+T16+U16+V16)*AG16),(L16*AP16)) -> 0 | Z16: 0.2 | AA16: 0.18 | AB16: 0.1 | AD16: 0.1 | AG16: 0.025 | AZ16: =AZ15 -> 80
A17: 09109913 | B17: KASTHURI METHI | D17: SCL | E17: =IF(D17="SCL",G17,H17) -> 1079 | G17: 1079 | H17: =ROUND(I17,0) -> 0 | I17: =IF(AND(L17<>"",L17<>0),ROUND(J17/L17,0),0) -> 0 | J17: =IF(C17="SG",ROUND((P17+Q17+R17+T17+V17+W17+X17),0),ROUND((P17+Q17+R17+S17+U17+W17+X17),0)) -> 0 | K17: =SUMIF(ProductList!$F$4:$F$493,A17,ProductList!$BA$4:$BA$493) -> 0 | L17: =SUMIF(ProductList!$F$4:$F$493,A17,ProductList!$V$4:$V$493) -> 0 | M17: =SUMIF(ProductList!$F$4:$F$493,A17,ProductList!$K$4:$K$493) -> 0 | N17: KG | O17: =IF(D17="SCL",100,AZ17) -> 100 | P17: =IF((K17*Y17)>(L17*AH17),(K17*Y17),(L17*AH17)) -> 0 | Q17: =IF((K17*Z17)>(L17*AI17),(K17*Z17),(L17*AI17)) -> 0 | R17: =IF(C17="SG", IF(((K17*1.1+P17+Q17+T17+V17)*AA17)>(L17*AJ17), (K17*1.1+P17+Q17+T17+V17)*AA17, L17*AJ17), IF(((K17*1.1+P17+Q17+S17+U17)*AA17)>(L17*AJ17), (K17*1.1+P17+Q17+S17+U17)*AA17, L17*AJ17) ) -> 0 | S17: =IF((K17*AB17)>(L17*AK17),(K17*AB17),(L17*AK17)) -> 0 | T17: =IF((K17*AC17)>(L17*AL17),(K17*AC17),(L17*AL17)) -> 0 | U17: =IF((K17*AD17)>(L17*AM17),(K17*AD17),(L17*AM17)) -> 0 | V17: =IF((K17*AE17)>(L17*AN17),(K17*AE17),(L17*AN17)) -> 0 | W17: =IF((K17*AF17)>(L17*AO17),(K17*AF17),(L17*AO17)) -> 0 | X17: =IF((((K17)*1.1+P17+Q17+S17+T17+U17+V17)*AG17)>(L17*AP17),(((K17)*1.1+P17+Q17+S17+T17+U17+V17)*AG17),(L17*AP17)) -> 0 | AZ17: =AZ16 -> 80
A18: 10063011 | B18: BASMATI RICE | E18: =IF(D18="SCL",G18,H18) -> 374 | G18: 268 | H18: =ROUND(I18,0) -> 374 | I18: =IF(AND(L18<>"",L18<>0),ROUND(J18/L18,0),0) -> 374 | J18: =IF(C18="SG",ROUND((P18+Q18+R18+T18+V18+W18+X18),0),ROUND((P18+Q18+R18+S18+U18+W18+X18),0)) -> 1781196 | K18: =SUMIF(ProductList!$F$4:$F$493,A18,ProductList!$BA$4:$BA$493) -> 2517592 | L18: =SUMIF(ProductList!$F$4:$F$493,A18,ProductList!$V$4:$V$493) -> 4760 | M18: =SUMIF(ProductList!$F$4:$F$493,A18,ProductList!$K$4:$K$493) -> 0 | N18: KG | O18: =IF(D18="SCL",100,AZ18) -> 80 | P18: =IF((K18*Y18)>(L18*AH18),(K18*Y18),(L18*AH18)) -> 0 | Q18: =IF((K18*Z18)>(L18*AI18),(K18*Z18),(L18*AI18)) -> 503518.4 | R18: =IF(C18="SG", IF(((K18*1.1+P18+Q18+T18+V18)*AA18)>(L18*AJ18), (K18*1.1+P18+Q18+T18+V18)*AA18, L18*AJ18), IF(((K18*1.1+P18+Q18+S18+U18)*AA18)>(L18*AJ18), (K18*1.1+P18+Q18+S18+U18)*AA18, L18*AJ18) ) -> 679749.84 | S18: =IF((K18*AB18)>(L18*AK18),(K18*AB18),(L18*AK18)) -> 251759.2 | T18: =IF((K18*AC18)>(L18*AL18),(K18*AC18),(L18*AL18)) -> 0 | U18: =IF((K18*AD18)>(L18*AM18),(K18*AD18),(L18*AM18)) -> 251759.2 | V18: =IF((K18*AE18)>(L18*AN18),(K18*AE18),(L18*AN18)) -> 0 | W18: =IF((K18*AF18)>(L18*AO18),(K18*AF18),(L18*AO18)) -> 0 | X18: =IF((((K18)*1.1+P18+Q18+S18+T18+U18+V18)*AG18)>(L18*AP18),(((K18)*1.1+P18+Q18+S18+T18+U18+V18)*AG18),(L18*AP18)) -> 94409.7 | Z18: 0.2 | AA18: 0.18 | AB18: 0.1 | AD18: 0.1 | AG18: 0.025 | AI18: 80 | AM18: 40 | AZ18: =AZ17 -> 80
A19: 10063019 | B19: RICE OTHERS | D19: SCL | E19: =IF(D19="SCL",G19,H19) -> 80 | F19: L | G19: 80 | H19: =ROUND(I19,0) -> 0 | I19: =IF(AND(L19<>"",L19<>0),ROUND(J19/L19,0),0) -> 0 | J19: =IF(C19="SG",ROUND((P19+Q19+R19+T19+V19+W19+X19),0),ROUND((P19+Q19+R19+S19+U19+W19+X19),0)) -> 0 | K19: =SUMIF(ProductList!$F$4:$F$493,A19,ProductList!$BA$4:$BA$493) -> 0 | L19: =SUMIF(ProductList!$F$4:$F$493,A19,ProductList!$V$4:$V$493) -> 0 | M19: =SUMIF(ProductList!$F$4:$F$493,A19,ProductList!$K$4:$K$493) -> 0 | N19: KG | O19: =IF(D19="SCL",100,AZ19) -> 100 | P19: =IF((K19*Y19)>(L19*AH19),(K19*Y19),(L19*AH19)) -> 0 | Q19: =IF((K19*Z19)>(L19*AI19),(K19*Z19),(L19*AI19)) -> 0 | R19: =IF(C19="SG", IF(((K19*1.1+P19+Q19+T19+V19)*AA19)>(L19*AJ19), (K19*1.1+P19+Q19+T19+V19)*AA19, L19*AJ19), IF(((K19*1.1+P19+Q19+S19+U19)*AA19)>(L19*AJ19), (K19*1.1+P19+Q19+S19+U19)*AA19, L19*AJ19) ) -> 0 | S19: =IF((K19*AB19)>(L19*AK19),(K19*AB19),(L19*AK19)) -> 0 | T19: =IF((K19*AC19)>(L19*AL19),(K19*AC19),(L19*AL19)) -> 0 | U19: =IF((K19*AD19)>(L19*AM19),(K19*AD19),(L19*AM19)) -> 0 | V19: =IF((K19*AE19)>(L19*AN19),(K19*AE19),(L19*AN19)) -> 0 | W19: =IF((K19*AF19)>(L19*AO19),(K19*AF19),(L19*AO19)) -> 0 | X19: =IF((((K19)*1.1+P19+Q19+S19+T19+U19+V19)*AG19)>(L19*AP19),(((K19)*1.1+P19+Q19+S19+T19+U19+V19)*AG19),(L19*AP19)) -> 0 | Z19: 0.2 | AA19: 0.18 | AB19: 0.1 | AD19: 0.1 | AG19: 0.025 | AI19: 80 | AM19: 40 | AZ19: =AZ18 -> 80
A20: 10082190 | B20: MILLETS - OTHERS | D20: SCL | E20: =IF(D20="SCL",G20,H20) -> 300 | G20: 300 | H20: =ROUND(I20,0) -> 0 | I20: =IF(AND(L20<>"",L20<>0),ROUND(J20/L20,0),0) -> 0 | J20: =IF(C20="SG",ROUND((P20+Q20+R20+T20+V20+W20+X20),0),ROUND((P20+Q20+R20+S20+U20+W20+X20),0)) -> 0 | K20: =SUMIF(ProductList!$F$4:$F$493,A20,ProductList!$BA$4:$BA$493) -> 0 | L20: =SUMIF(ProductList!$F$4:$F$493,A20,ProductList!$V$4:$V$493) -> 0 | M20: =SUMIF(ProductList!$F$4:$F$493,A20,ProductList!$K$4:$K$493) -> 0 | N20: KG | O20: =IF(D20="SCL",100,AZ20) -> 100 | P20: =IF((K20*Y20)>(L20*AH20),(K20*Y20),(L20*AH20)) -> 0 | Q20: =IF((K20*Z20)>(L20*AI20),(K20*Z20),(L20*AI20)) -> 0 | R20: =IF(C20="SG", IF(((K20*1.1+P20+Q20+T20+V20)*AA20)>(L20*AJ20), (K20*1.1+P20+Q20+T20+V20)*AA20, L20*AJ20), IF(((K20*1.1+P20+Q20+S20+U20)*AA20)>(L20*AJ20), (K20*1.1+P20+Q20+S20+U20)*AA20, L20*AJ20) ) -> 0 | S20: =IF((K20*AB20)>(L20*AK20),(K20*AB20),(L20*AK20)) -> 0 | T20: =IF((K20*AC20)>(L20*AL20),(K20*AC20),(L20*AL20)) -> 0 | U20: =IF((K20*AD20)>(L20*AM20),(K20*AD20),(L20*AM20)) -> 0 | V20: =IF((K20*AE20)>(L20*AN20),(K20*AE20),(L20*AN20)) -> 0 | W20: =IF((K20*AF20)>(L20*AO20),(K20*AF20),(L20*AO20)) -> 0 | X20: =IF((((K20)*1.1+P20+Q20+S20+T20+U20+V20)*AG20)>(L20*AP20),(((K20)*1.1+P20+Q20+S20+T20+U20+V20)*AG20),(L20*AP20)) -> 0 | Z20: 0.2 | AA20: 0.18 | AD20: 0.1 | AG20: 0.025 | AZ20: =AZ19 -> 80
A21: 10089090 | B21: MILLETS | E21: =IF(D21="SCL",G21,H21) -> 0 | G21: 107 | H21: =ROUND(I21,0) -> 0 | I21: =IF(AND(L21<>"",L21<>0),ROUND(J21/L21,0),0) -> 0 | J21: =IF(C21="SG",ROUND((P21+Q21+R21+T21+V21+W21+X21),0),ROUND((P21+Q21+R21+S21+U21+W21+X21),0)) -> 0 | K21: =SUMIF(ProductList!$F$4:$F$493,A21,ProductList!$BA$4:$BA$493) -> 0 | L21: =SUMIF(ProductList!$F$4:$F$493,A21,ProductList!$V$4:$V$493) -> 0 | M21: =SUMIF(ProductList!$F$4:$F$493,A21,ProductList!$K$4:$K$493) -> 0 | N21: KG | O21: =IF(D21="SCL",100,AZ21) -> 80 | P21: =IF((K21*Y21)>(L21*AH21),(K21*Y21),(L21*AH21)) -> 0 | Q21: =IF((K21*Z21)>(L21*AI21),(K21*Z21),(L21*AI21)) -> 0 | R21: =IF(C21="SG", IF(((K21*1.1+P21+Q21+T21+V21)*AA21)>(L21*AJ21), (K21*1.1+P21+Q21+T21+V21)*AA21, L21*AJ21), IF(((K21*1.1+P21+Q21+S21+U21)*AA21)>(L21*AJ21), (K21*1.1+P21+Q21+S21+U21)*AA21, L21*AJ21) ) -> 0 | S21: =IF((K21*AB21)>(L21*AK21),(K21*AB21),(L21*AK21)) -> 0 | T21: =IF((K21*AC21)>(L21*AL21),(K21*AC21),(L21*AL21)) -> 0 | U21: =IF((K21*AD21)>(L21*AM21),(K21*AD21),(L21*AM21)) -> 0 | V21: =IF((K21*AE21)>(L21*AN21),(K21*AE21),(L21*AN21)) -> 0 | W21: =IF((K21*AF21)>(L21*AO21),(K21*AF21),(L21*AO21)) -> 0 | X21: =IF((((K21)*1.1+P21+Q21+S21+T21+U21+V21)*AG21)>(L21*AP21),(((K21)*1.1+P21+Q21+S21+T21+U21+V21)*AG21),(L21*AP21)) -> 0 | AZ21: =AZ20 -> 80
A22: 11031110 | B22: WHEAT GROATS | D22: NORM | E22: =IF(D22="SCL",G22,H22) -> 0 | F22: L | G22: 159 | H22: =ROUND(I22,0) -> 0 | I22: =IF(AND(L22<>"",L22<>0),ROUND(J22/L22,0),0) -> 0 | J22: =IF(C22="SG",ROUND((P22+Q22+R22+T22+V22+W22+X22),0),ROUND((P22+Q22+R22+S22+U22+W22+X22),0)) -> 0 | K22: =SUMIF(ProductList!$F$4:$F$493,A22,ProductList!$BA$4:$BA$493) -> 0 | L22: =SUMIF(ProductList!$F$4:$F$493,A22,ProductList!$V$4:$V$493) -> 0 | M22: =SUMIF(ProductList!$F$4:$F$493,A22,ProductList!$K$4:$K$493) -> 0 | N22: KG | O22: =IF(D22="SCL",100,AZ22) -> 80 | P22: =IF((K22*Y22)>(L22*AH22),(K22*Y22),(L22*AH22)) -> 0 | Q22: =IF((K22*Z22)>(L22*AI22),(K22*Z22),(L22*AI22)) -> 0 | R22: =IF(C22="SG", IF(((K22*1.1+P22+Q22+T22+V22)*AA22)>(L22*AJ22), (K22*1.1+P22+Q22+T22+V22)*AA22, L22*AJ22), IF(((K22*1.1+P22+Q22+S22+U22)*AA22)>(L22*AJ22), (K22*1.1+P22+Q22+S22+U22)*AA22, L22*AJ22) ) -> 0 | S22: =IF((K22*AB22)>(L22*AK22),(K22*AB22),(L22*AK22)) -> 0 | T22: =IF((K22*AC22)>(L22*AL22),(K22*AC22),(L22*AL22)) -> 0 | U22: =IF((K22*AD22)>(L22*AM22),(K22*AD22),(L22*AM22)) -> 0 | V22: =IF((K22*AE22)>(L22*AN22),(K22*AE22),(L22*AN22)) -> 0 | W22: =IF((K22*AF22)>(L22*AO22),(K22*AF22),(L22*AO22)) -> 0 | X22: =IF((((K22)*1.1+P22+Q22+S22+T22+U22+V22)*AG22)>(L22*AP22),(((K22)*1.1+P22+Q22+S22+T22+U22+V22)*AG22),(L22*AP22)) -> 0 | Z22: 0.2 | AA22: 0.18 | AB22: 0.1 | AD22: 0.25 | AG22: 0.025 | AZ22: =AZ21 -> 80
A23: 11032000 | B23: RICE PELLETS | E23: =IF(D23="SCL",G23,H23) -> 0 | F23: L | H23: =ROUND(I23,0) -> 0 | I23: =IF(AND(L23<>"",L23<>0),ROUND(J23/L23,0),0) -> 0 | J23: =IF(C23="SG",ROUND((P23+Q23+R23+T23+V23+W23+X23),0),ROUND((P23+Q23+R23+S23+U23+W23+X23),0)) -> 0 | K23: =SUMIF(ProductList!$F$4:$F$493,A23,ProductList!$BA$4:$BA$493) -> 0 | L23: =SUMIF(ProductList!$F$4:$F$493,A23,ProductList!$V$4:$V$493) -> 0 | M23: =SUMIF(ProductList!$F$4:$F$493,A23,ProductList!$K$4:$K$493) -> 0 | N23: KG | O23: =IF(D23="SCL",100,AZ23) -> 80 | P23: =IF((K23*Y23)>(L23*AH23),(K23*Y23),(L23*AH23)) -> 0 | Q23: =IF((K23*Z23)>(L23*AI23),(K23*Z23),(L23*AI23)) -> 0 | R23: =IF(C23="SG", IF(((K23*1.1+P23+Q23+T23+V23)*AA23)>(L23*AJ23), (K23*1.1+P23+Q23+T23+V23)*AA23, L23*AJ23), IF(((K23*1.1+P23+Q23+S23+U23)*AA23)>(L23*AJ23), (K23*1.1+P23+Q23+S23+U23)*AA23, L23*AJ23) ) -> 0 | S23: =IF((K23*AB23)>(L23*AK23),(K23*AB23),(L23*AK23)) -> 0 | T23: =IF((K23*AC23)>(L23*AL23),(K23*AC23),(L23*AL23)) -> 0 | U23: =IF((K23*AD23)>(L23*AM23),(K23*AD23),(L23*AM23)) -> 0 | V23: =IF((K23*AE23)>(L23*AN23),(K23*AE23),(L23*AN23)) -> 0 | W23: =IF((K23*AF23)>(L23*AO23),(K23*AF23),(L23*AO23)) -> 0 | X23: =IF((((K23)*1.1+P23+Q23+S23+T23+U23+V23)*AG23)>(L23*AP23),(((K23)*1.1+P23+Q23+S23+T23+U23+V23)*AG23),(L23*AP23)) -> 0 | Z23: 0.2 | AA23: 0.18 | AD23: 0.1 | AG23: 0.025 | AZ23: =AZ22 -> 80
A24: 11042900 | E24: =IF(D24="SCL",G24,H24) -> 0 | G24: 334 | H24: =ROUND(I24,0) -> 0 | I24: =IF(AND(L24<>"",L24<>0),ROUND(J24/L24,0),0) -> 0 | J24: =IF(C24="SG",ROUND((P24+Q24+R24+T24+V24+W24+X24),0),ROUND((P24+Q24+R24+S24+U24+W24+X24),0)) -> 0 | K24: =SUMIF(ProductList!$F$4:$F$493,A24,ProductList!$BA$4:$BA$493) -> 0 | L24: =SUMIF(ProductList!$F$4:$F$493,A24,ProductList!$V$4:$V$493) -> 0 | M24: =SUMIF(ProductList!$F$4:$F$493,A24,ProductList!$K$4:$K$493) -> 0 | N24: KG | O24: =IF(D24="SCL",100,AZ24) -> 80 | P24: =IF((K24*Y24)>(L24*AH24),(K24*Y24),(L24*AH24)) -> 0 | Q24: =IF((K24*Z24)>(L24*AI24),(K24*Z24),(L24*AI24)) -> 0 | R24: =IF(C24="SG", IF(((K24*1.1+P24+Q24+T24+V24)*AA24)>(L24*AJ24), (K24*1.1+P24+Q24+T24+V24)*AA24, L24*AJ24), IF(((K24*1.1+P24+Q24+S24+U24)*AA24)>(L24*AJ24), (K24*1.1+P24+Q24+S24+U24)*AA24, L24*AJ24) ) -> 0 | S24: =IF((K24*AB24)>(L24*AK24),(K24*AB24),(L24*AK24)) -> 0 | T24: =IF((K24*AC24)>(L24*AL24),(K24*AC24),(L24*AL24)) -> 0 | U24: =IF((K24*AD24)>(L24*AM24),(K24*AD24),(L24*AM24)) -> 0 | V24: =IF((K24*AE24)>(L24*AN24),(K24*AE24),(L24*AN24)) -> 0 | W24: =IF((K24*AF24)>(L24*AO24),(K24*AF24),(L24*AO24)) -> 0 | X24: =IF((((K24)*1.1+P24+Q24+S24+T24+U24+V24)*AG24)>(L24*AP24),(((K24)*1.1+P24+Q24+S24+T24+U24+V24)*AG24),(L24*AP24)) -> 0 | AZ24: =AZ23 -> 80
A25: 11043000 | B25: GROUNDED CEREALS | D25: NORM | E25: =IF(D25="SCL",G25,H25) -> 0 | H25: =ROUND(I25,0) -> 0 | I25: =IF(AND(L25<>"",L25<>0),ROUND(J25/L25,0),0) -> 0 | J25: =IF(C25="SG",ROUND((P25+Q25+R25+T25+V25+W25+X25),0),ROUND((P25+Q25+R25+S25+U25+W25+X25),0)) -> 0 | K25: =SUMIF(ProductList!$F$4:$F$493,A25,ProductList!$BA$4:$BA$493) -> 0 | L25: =SUMIF(ProductList!$F$4:$F$493,A25,ProductList!$V$4:$V$493) -> 0 | M25: =SUMIF(ProductList!$F$4:$F$493,A25,ProductList!$K$4:$K$493) -> 0 | N25: KG | O25: =IF(D25="SCL",100,AZ25) -> 80 | P25: =IF((K25*Y25)>(L25*AH25),(K25*Y25),(L25*AH25)) -> 0 | Q25: =IF((K25*Z25)>(L25*AI25),(K25*Z25),(L25*AI25)) -> 0 | R25: =IF(C25="SG", IF(((K25*1.1+P25+Q25+T25+V25)*AA25)>(L25*AJ25), (K25*1.1+P25+Q25+T25+V25)*AA25, L25*AJ25), IF(((K25*1.1+P25+Q25+S25+U25)*AA25)>(L25*AJ25), (K25*1.1+P25+Q25+S25+U25)*AA25, L25*AJ25) ) -> 0 | S25: =IF((K25*AB25)>(L25*AK25),(K25*AB25),(L25*AK25)) -> 0 | T25: =IF((K25*AC25)>(L25*AL25),(K25*AC25),(L25*AL25)) -> 0 | U25: =IF((K25*AD25)>(L25*AM25),(K25*AD25),(L25*AM25)) -> 0 | V25: =IF((K25*AE25)>(L25*AN25),(K25*AE25),(L25*AN25)) -> 0 | W25: =IF((K25*AF25)>(L25*AO25),(K25*AF25),(L25*AO25)) -> 0 | X25: =IF((((K25)*1.1+P25+Q25+S25+T25+U25+V25)*AG25)>(L25*AP25),(((K25)*1.1+P25+Q25+S25+T25+U25+V25)*AG25),(L25*AP25)) -> 0 | Z25: 0.2 | AA25: 0.18 | AD25: 0.25 | AG25: 0.025 | AI25: 65 | AM25: 80 | AZ25: =AZ24 -> 80
A26: 11061010 | B26: BLACK - GRAM FLOUR | E26: =IF(D26="SCL",G26,H26) -> 0 | F26: L | H26: =ROUND(I26,0) -> 0 | I26: =IF(AND(L26<>"",L26<>0),ROUND(J26/L26,0),0) -> 0 | J26: =IF(C26="SG",ROUND((P26+Q26+R26+T26+V26+W26+X26),0),ROUND((P26+Q26+R26+S26+U26+W26+X26),0)) -> 0 | K26: =SUMIF(ProductList!$F$4:$F$493,A26,ProductList!$BA$4:$BA$493) -> 0 | L26: =SUMIF(ProductList!$F$4:$F$493,A26,ProductList!$V$4:$V$493) -> 0 | M26: =SUMIF(ProductList!$F$4:$F$493,A26,ProductList!$K$4:$K$493) -> 0 | N26: KG | O26: =IF(D26="SCL",100,AZ26) -> 80 | P26: =IF((K26*Y26)>(L26*AH26),(K26*Y26),(L26*AH26)) -> 0 | Q26: =IF((K26*Z26)>(L26*AI26),(K26*Z26),(L26*AI26)) -> 0 | R26: =IF(C26="SG", IF(((K26*1.1+P26+Q26+T26+V26)*AA26)>(L26*AJ26), (K26*1.1+P26+Q26+T26+V26)*AA26, L26*AJ26), IF(((K26*1.1+P26+Q26+S26+U26)*AA26)>(L26*AJ26), (K26*1.1+P26+Q26+S26+U26)*AA26, L26*AJ26) ) -> 0 | S26: =IF((K26*AB26)>(L26*AK26),(K26*AB26),(L26*AK26)) -> 0 | T26: =IF((K26*AC26)>(L26*AL26),(K26*AC26),(L26*AL26)) -> 0 | U26: =IF((K26*AD26)>(L26*AM26),(K26*AD26),(L26*AM26)) -> 0 | V26: =IF((K26*AE26)>(L26*AN26),(K26*AE26),(L26*AN26)) -> 0 | W26: =IF((K26*AF26)>(L26*AO26),(K26*AF26),(L26*AO26)) -> 0 | X26: =IF((((K26)*1.1+P26+Q26+S26+T26+U26+V26)*AG26)>(L26*AP26),(((K26)*1.1+P26+Q26+S26+T26+U26+V26)*AG26),(L26*AP26)) -> 0 | Z26: 0.2 | AA26: 0.18 | AG26: 0.025 | AZ26: =AZ25 -> 80
A27: 13012000 | B27: GUM ARABIC | D27: NORM | E27: =IF(D27="SCL",G27,H27) -> 1130 | H27: =ROUND(I27,0) -> 1130 | I27: =IF(AND(L27<>"",L27<>0),ROUND(J27/L27,0),0) -> 1130 | J27: =IF(C27="SG",ROUND((P27+Q27+R27+T27+V27+W27+X27),0),ROUND((P27+Q27+R27+S27+U27+W27+X27),0)) -> 67824 | K27: =SUMIF(ProductList!$F$4:$F$493,A27,ProductList!$BA$4:$BA$493) -> 195178.4 | L27: =SUMIF(ProductList!$F$4:$F$493,A27,ProductList!$V$4:$V$493) -> 60 | M27: =SUMIF(ProductList!$F$4:$F$493,A27,ProductList!$K$4:$K$493) -> 0 | N27: KG | O27: =IF(D27="SCL",100,AZ27) -> 80 | P27: =IF((K27*Y27)>(L27*AH27),(K27*Y27),(L27*AH27)) -> 0 | Q27: =IF((K27*Z27)>(L27*AI27),(K27*Z27),(L27*AI27)) -> 0 | R27: =IF(C27="SG", IF(((K27*1.1+P27+Q27+T27+V27)*AA27)>(L27*AJ27), (K27*1.1+P27+Q27+T27+V27)*AA27, L27*AJ27), IF(((K27*1.1+P27+Q27+S27+U27)*AA27)>(L27*AJ27), (K27*1.1+P27+Q27+S27+U27)*AA27, L27*AJ27) ) -> 42158.534 | S27: =IF((K27*AB27)>(L27*AK27),(K27*AB27),(L27*AK27)) -> 19517.84 | T27: =IF((K27*AC27)>(L27*AL27),(K27*AC27),(L27*AL27)) -> 11710.704 | U27: =IF((K27*AD27)>(L27*AM27),(K27*AD27),(L27*AM27)) -> 0 | V27: =IF((K27*AE27)>(L27*AN27),(K27*AE27),(L27*AN27)) -> 0 | W27: =IF((K27*AF27)>(L27*AO27),(K27*AF27),(L27*AO27)) -> 0 | X27: =IF((((K27)*1.1+P27+Q27+S27+T27+U27+V27)*AG27)>(L27*AP27),(((K27)*1.1+P27+Q27+S27+T27+U27+V27)*AG27),(L27*AP27)) -> 6148.1196 | AA27: 0.18 | AB27: 0.1 | AC27: 0.06 | AG27: 0.025 | AZ27: =AZ26 -> 80
A28: 15089000 | B28: GROUNDNUT OIL | D28: NORM | E28: =IF(D28="SCL",G28,H28) -> 0 | F28: S | H28: =ROUND(I28,0) -> 0 | I28: =IF(AND(L28<>"",L28<>0),ROUND(J28/L28,0),0) -> 0 | J28: =IF(C28="SG",ROUND((P28+Q28+R28+T28+V28+W28+X28),0),ROUND((P28+Q28+R28+S28+U28+W28+X28),0)) -> 0 | K28: =SUMIF(ProductList!$F$4:$F$493,A28,ProductList!$BA$4:$BA$493) -> 0 | L28: =SUMIF(ProductList!$F$4:$F$493,A28,ProductList!$V$4:$V$493) -> 0 | M28: =SUMIF(ProductList!$F$4:$F$493,A28,ProductList!$K$4:$K$493) -> 0 | N28: KG | O28: =IF(D28="SCL",100,AZ28) -> 80 | P28: =IF((K28*Y28)>(L28*AH28),(K28*Y28),(L28*AH28)) -> 0 | Q28: =IF((K28*Z28)>(L28*AI28),(K28*Z28),(L28*AI28)) -> 0 | R28: =IF(C28="SG", IF(((K28*1.1+P28+Q28+T28+V28)*AA28)>(L28*AJ28), (K28*1.1+P28+Q28+T28+V28)*AA28, L28*AJ28), IF(((K28*1.1+P28+Q28+S28+U28)*AA28)>(L28*AJ28), (K28*1.1+P28+Q28+S28+U28)*AA28, L28*AJ28) ) -> 0 | S28: =IF((K28*AB28)>(L28*AK28),(K28*AB28),(L28*AK28)) -> 0 | T28: =IF((K28*AC28)>(L28*AL28),(K28*AC28),(L28*AL28)) -> 0 | U28: =IF((K28*AD28)>(L28*AM28),(K28*AD28),(L28*AM28)) -> 0 | V28: =IF((K28*AE28)>(L28*AN28),(K28*AE28),(L28*AN28)) -> 0 | W28: =IF((K28*AF28)>(L28*AO28),(K28*AF28),(L28*AO28)) -> 0 | X28: =IF((((K28)*1.1+P28+Q28+S28+T28+U28+V28)*AG28)>(L28*AP28),(((K28)*1.1+P28+Q28+S28+T28+U28+V28)*AG28),(L28*AP28)) -> 0 | Z28: 0.2 | AA28: 0.18 | AD28: 0.1 | AI28: 105 | AM28: 75 | AZ28: =AZ27 -> 80
A29: 15149900 | B29: MUSTARD OIL | E29: =IF(D29="SCL",G29,H29) -> 0 | G29: 357 | H29: =ROUND(I29,0) -> 0 | I29: =IF(AND(L29<>"",L29<>0),ROUND(J29/L29,0),0) -> 0 | J29: =IF(C29="SG",ROUND((P29+Q29+R29+T29+V29+W29+X29),0),ROUND((P29+Q29+R29+S29+U29+W29+X29),0)) -> 0 | K29: =SUMIF(ProductList!$F$4:$F$493,A29,ProductList!$BA$4:$BA$493) -> 0 | L29: =SUMIF(ProductList!$F$4:$F$493,A29,ProductList!$V$4:$V$493) -> 0 | M29: =SUMIF(ProductList!$F$4:$F$493,A29,ProductList!$K$4:$K$493) -> 0 | N29: KG | O29: =IF(D29="SCL",100,AZ29) -> 80 | P29: =IF((K29*Y29)>(L29*AH29),(K29*Y29),(L29*AH29)) -> 0 | Q29: =IF((K29*Z29)>(L29*AI29),(K29*Z29),(L29*AI29)) -> 0 | R29: =IF(C29="SG", IF(((K29*1.1+P29+Q29+T29+V29)*AA29)>(L29*AJ29), (K29*1.1+P29+Q29+T29+V29)*AA29, L29*AJ29), IF(((K29*1.1+P29+Q29+S29+U29)*AA29)>(L29*AJ29), (K29*1.1+P29+Q29+S29+U29)*AA29, L29*AJ29) ) -> 0 | S29: =IF((K29*AB29)>(L29*AK29),(K29*AB29),(L29*AK29)) -> 0 | T29: =IF((K29*AC29)>(L29*AL29),(K29*AC29),(L29*AL29)) -> 0 | U29: =IF((K29*AD29)>(L29*AM29),(K29*AD29),(L29*AM29)) -> 0 | V29: =IF((K29*AE29)>(L29*AN29),(K29*AE29),(L29*AN29)) -> 0 | W29: =IF((K29*AF29)>(L29*AO29),(K29*AF29),(L29*AO29)) -> 0 | X29: =IF((((K29)*1.1+P29+Q29+S29+T29+U29+V29)*AG29)>(L29*AP29),(((K29)*1.1+P29+Q29+S29+T29+U29+V29)*AG29),(L29*AP29)) -> 0 | Z29: 0.2 | AA29: 0.18 | AB29: 0.1 | AD29: 0.1 | AG29: 0.025 | AI29: 110 | AM29: 75 | AZ29: =AZ28 -> 80
A30: 151530 | B30: CASTOR OIL AND ITS FRACTIONS | D30: NORM | E30: =IF(D30="SCL",G30,H30) -> 0 | H30: =ROUND(I30,0) -> 0 | I30: =IF(AND(L30<>"",L30<>0),ROUND(J30/L30,0),0) -> 0 | J30: =IF(C30="SG",ROUND((P30+Q30+R30+T30+V30+W30+X30),0),ROUND((P30+Q30+R30+S30+U30+W30+X30),0)) -> 0 | K30: =SUMIF(ProductList!$F$4:$F$493,A30,ProductList!$BA$4:$BA$493) -> 0 | L30: =SUMIF(ProductList!$F$4:$F$493,A30,ProductList!$V$4:$V$493) -> 0 | M30: =SUMIF(ProductList!$F$4:$F$493,A30,ProductList!$K$4:$K$493) -> 0 | N30: KG | O30: =IF(D30="SCL",100,AZ30) -> 80 | P30: =IF((K30*Y30)>(L30*AH30),(K30*Y30),(L30*AH30)) -> 0 | Q30: =IF((K30*Z30)>(L30*AI30),(K30*Z30),(L30*AI30)) -> 0 | R30: =IF(C30="SG", IF(((K30*1.1+P30+Q30+T30+V30)*AA30)>(L30*AJ30), (K30*1.1+P30+Q30+T30+V30)*AA30, L30*AJ30), IF(((K30*1.1+P30+Q30+S30+U30)*AA30)>(L30*AJ30), (K30*1.1+P30+Q30+S30+U30)*AA30, L30*AJ30) ) -> 0 | S30: =IF((K30*AB30)>(L30*AK30),(K30*AB30),(L30*AK30)) -> 0 | T30: =IF((K30*AC30)>(L30*AL30),(K30*AC30),(L30*AL30)) -> 0 | U30: =IF((K30*AD30)>(L30*AM30),(K30*AD30),(L30*AM30)) -> 0 | V30: =IF((K30*AE30)>(L30*AN30),(K30*AE30),(L30*AN30)) -> 0 | W30: =IF((K30*AF30)>(L30*AO30),(K30*AF30),(L30*AO30)) -> 0 | X30: =IF((((K30)*1.1+P30+Q30+S30+T30+U30+V30)*AG30)>(L30*AP30),(((K30)*1.1+P30+Q30+S30+T30+U30+V30)*AG30),(L30*AP30)) -> 0 | Z30: 0.2 | AA30: 0.18 | AB30: 0.1 | AC30: 0.06 | AD30: 0.1 | AG30: 0.025 | AM30: 110 | AN30: 12 | AZ30: =AZ29 -> 80
A31: 151550 | B31: GINGELLY OIL | D31: NORM | E31: =IF(D31="SCL",G31,H31) -> 0 | F31: S | G31: 507 | H31: =ROUND(I31,0) -> 0 | I31: =IF(AND(L31<>"",L31<>0),ROUND(J31/L31,0),0) -> 0 | J31: =IF(C31="SG",ROUND((P31+Q31+R31+T31+V31+W31+X31),0),ROUND((P31+Q31+R31+S31+U31+W31+X31),0)) -> 0 | K31: =SUMIF(ProductList!$F$4:$F$493,A31,ProductList!$BA$4:$BA$493) -> 0 | L31: =SUMIF(ProductList!$F$4:$F$493,A31,ProductList!$V$4:$V$493) -> 0 | M31: =SUMIF(ProductList!$F$4:$F$493,A31,ProductList!$K$4:$K$493) -> 0 | N31: KG | O31: =IF(D31="SCL",100,AZ31) -> 80 | P31: =IF((K31*Y31)>(L31*AH31),(K31*Y31),(L31*AH31)) -> 0 | Q31: =IF((K31*Z31)>(L31*AI31),(K31*Z31),(L31*AI31)) -> 0 | R31: =IF(C31="SG", IF(((K31*1.1+P31+Q31+T31+V31)*AA31)>(L31*AJ31), (K31*1.1+P31+Q31+T31+V31)*AA31, L31*AJ31), IF(((K31*1.1+P31+Q31+S31+U31)*AA31)>(L31*AJ31), (K31*1.1+P31+Q31+S31+U31)*AA31, L31*AJ31) ) -> 0 | S31: =IF((K31*AB31)>(L31*AK31),(K31*AB31),(L31*AK31)) -> 0 | T31: =IF((K31*AC31)>(L31*AL31),(K31*AC31),(L31*AL31)) -> 0 | U31: =IF((K31*AD31)>(L31*AM31),(K31*AD31),(L31*AM31)) -> 0 | V31: =IF((K31*AE31)>(L31*AN31),(K31*AE31),(L31*AN31)) -> 0 | W31: =IF((K31*AF31)>(L31*AO31),(K31*AF31),(L31*AO31)) -> 0 | X31: =IF((((K31)*1.1+P31+Q31+S31+T31+U31+V31)*AG31)>(L31*AP31),(((K31)*1.1+P31+Q31+S31+T31+U31+V31)*AG31),(L31*AP31)) -> 0 | Z31: 0.2 | AA31: 0.18 | AB31: 0.1 | AC31: 0.06 | AG31: 0.025 | AM31: 30 | AN31: 12 | AZ31: =AZ30 -> 80
A32: 15162000 | B32: DALDA | D32: SCL | E32: =IF(D32="SCL",G32,H32) -> 160 | G32: 160 | H32: =ROUND(I32,0) -> 0 | I32: =IF(AND(L32<>"",L32<>0),ROUND(J32/L32,0),0) -> 0 | J32: =IF(C32="SG",ROUND((P32+Q32+R32+T32+V32+W32+X32),0),ROUND((P32+Q32+R32+S32+U32+W32+X32),0)) -> 0 | K32: =SUMIF(ProductList!$F$4:$F$493,A32,ProductList!$BA$4:$BA$493) -> 0 | L32: =SUMIF(ProductList!$F$4:$F$493,A32,ProductList!$V$4:$V$493) -> 0 | M32: =SUMIF(ProductList!$F$4:$F$493,A32,ProductList!$K$4:$K$493) -> 0 | N32: KG | O32: =IF(D32="SCL",100,AZ32) -> 100 | P32: =IF((K32*Y32)>(L32*AH32),(K32*Y32),(L32*AH32)) -> 0 | Q32: =IF((K32*Z32)>(L32*AI32),(K32*Z32),(L32*AI32)) -> 0 | R32: =IF(C32="SG", IF(((K32*1.1+P32+Q32+T32+V32)*AA32)>(L32*AJ32), (K32*1.1+P32+Q32+T32+V32)*AA32, L32*AJ32), IF(((K32*1.1+P32+Q32+S32+U32)*AA32)>(L32*AJ32), (K32*1.1+P32+Q32+S32+U32)*AA32, L32*AJ32) ) -> 0 | S32: =IF((K32*AB32)>(L32*AK32),(K32*AB32),(L32*AK32)) -> 0 | T32: =IF((K32*AC32)>(L32*AL32),(K32*AC32),(L32*AL32)) -> 0 | U32: =IF((K32*AD32)>(L32*AM32),(K32*AD32),(L32*AM32)) -> 0 | V32: =IF((K32*AE32)>(L32*AN32),(K32*AE32),(L32*AN32)) -> 0 | W32: =IF((K32*AF32)>(L32*AO32),(K32*AF32),(L32*AO32)) -> 0 | X32: =IF((((K32)*1.1+P32+Q32+S32+T32+U32+V32)*AG32)>(L32*AP32),(((K32)*1.1+P32+Q32+S32+T32+U32+V32)*AG32),(L32*AP32)) -> 0 | Z32: 0.15 | AA32: 0.18 | AG32: 0.025 | AI32: 120 | AM32: 145 | AZ32: =AZ31 -> 80
A33: 17029021 | B33: JAGGARY AND JAGGARY POWDER, PALM SUGAR | C33: NORM | D33: NORM | E33: =IF(D33="SCL",G33,H33) -> 0 | G33: 364 | H33: =ROUND(I33,0) -> 0 | I33: =IF(AND(L33<>"",L33<>0),ROUND(J33/L33,0),0) -> 0 | J33: =IF(C33="SG",ROUND((P33+Q33+R33+T33+V33+W33+X33),0),ROUND((P33+Q33+R33+S33+U33+W33+X33),0)) -> 0 | K33: =SUMIF(ProductList!$F$4:$F$493,A33,ProductList!$BA$4:$BA$493) -> 0 | L33: =SUMIF(ProductList!$F$4:$F$493,A33,ProductList!$V$4:$V$493) -> 0 | M33: =SUMIF(ProductList!$F$4:$F$493,A33,ProductList!$K$4:$K$493) -> 0 | N33: KG | O33: =IF(D33="SCL",100,AZ33) -> 80 | P33: =IF((K33*Y33)>(L33*AH33),(K33*Y33),(L33*AH33)) -> 0 | Q33: =IF((K33*Z33)>(L33*AI33),(K33*Z33),(L33*AI33)) -> 0 | R33: =IF(C33="SG", IF(((K33*1.1+P33+Q33+T33+V33)*AA33)>(L33*AJ33), (K33*1.1+P33+Q33+T33+V33)*AA33, L33*AJ33), IF(((K33*1.1+P33+Q33+S33+U33)*AA33)>(L33*AJ33), (K33*1.1+P33+Q33+S33+U33)*AA33, L33*AJ33) ) -> 0 | S33: =IF((K33*AB33)>(L33*AK33),(K33*AB33),(L33*AK33)) -> 0 | T33: =IF((K33*AC33)>(L33*AL33),(K33*AC33),(L33*AL33)) -> 0 | U33: =IF((K33*AD33)>(L33*AM33),(K33*AD33),(L33*AM33)) -> 0 | V33: =IF((K33*AE33)>(L33*AN33),(K33*AE33),(L33*AN33)) -> 0 | W33: =IF((K33*AF33)>(L33*AO33),(K33*AF33),(L33*AO33)) -> 0 | X33: =IF((((K33)*1.1+P33+Q33+S33+T33+U33+V33)*AG33)>(L33*AP33),(((K33)*1.1+P33+Q33+S33+T33+U33+V33)*AG33),(L33*AP33)) -> 0 | Z33: 0.2 | AA33: 0.18 | AB33: 0.1 | AC33: 0.06 | AG33: 0.025 | AM33: 180 | AN33: 200 | AZ33: =AZ32 -> 80
A34: 17029090 | B34: SUGAR BASED SNACK ITEM | D34: NORM | E34: =IF(D34="SCL",G34,H34) -> 0 | H34: =ROUND(I34,0) -> 0 | I34: =IF(AND(L34<>"",L34<>0),ROUND(J34/L34,0),0) -> 0 | J34: =IF(C34="SG",ROUND((P34+Q34+R34+T34+V34+W34+X34),0),ROUND((P34+Q34+R34+S34+U34+W34+X34),0)) -> 0 | K34: =SUMIF(ProductList!$F$4:$F$493,A34,ProductList!$BA$4:$BA$493) -> 0 | L34: =SUMIF(ProductList!$F$4:$F$493,A34,ProductList!$V$4:$V$493) -> 0 | M34: =SUMIF(ProductList!$F$4:$F$493,A34,ProductList!$K$4:$K$493) -> 0 | N34: KG | O34: =IF(D34="SCL",100,AZ34) -> 80 | P34: =IF((K34*Y34)>(L34*AH34),(K34*Y34),(L34*AH34)) -> 0 | Q34: =IF((K34*Z34)>(L34*AI34),(K34*Z34),(L34*AI34)) -> 0 | R34: =IF(C34="SG", IF(((K34*1.1+P34+Q34+T34+V34)*AA34)>(L34*AJ34), (K34*1.1+P34+Q34+T34+V34)*AA34, L34*AJ34), IF(((K34*1.1+P34+Q34+S34+U34)*AA34)>(L34*AJ34), (K34*1.1+P34+Q34+S34+U34)*AA34, L34*AJ34) ) -> 0 | S34: =IF((K34*AB34)>(L34*AK34),(K34*AB34),(L34*AK34)) -> 0 | T34: =IF((K34*AC34)>(L34*AL34),(K34*AC34),(L34*AL34)) -> 0 | U34: =IF((K34*AD34)>(L34*AM34),(K34*AD34),(L34*AM34)) -> 0 | V34: =IF((K34*AE34)>(L34*AN34),(K34*AE34),(L34*AN34)) -> 0 | W34: =IF((K34*AF34)>(L34*AO34),(K34*AF34),(L34*AO34)) -> 0 | X34: =IF((((K34)*1.1+P34+Q34+S34+T34+U34+V34)*AG34)>(L34*AP34),(((K34)*1.1+P34+Q34+S34+T34+U34+V34)*AG34),(L34*AP34)) -> 0 | Z34: 0.2 | AA34: 0.18 | AB34: 0.1 | AC34: 0.06 | AG34: 0.025 | AM34: 180 | AN34: 200 | AZ34: =AZ33 -> 80
A35: 17049090 | B35: SUGAR CANDY | E35: =IF(D35="SCL",G35,H35) -> 0 | F35: S | H35: =ROUND(I35,0) -> 0 | I35: =IF(AND(L35<>"",L35<>0),ROUND(J35/L35,0),0) -> 0 | J35: =IF(C35="SG",ROUND((P35+Q35+R35+T35+V35+W35+X35),0),ROUND((P35+Q35+R35+S35+U35+W35+X35),0)) -> 0 | K35: =SUMIF(ProductList!$F$4:$F$493,A35,ProductList!$BA$4:$BA$493) -> 0 | L35: =SUMIF(ProductList!$F$4:$F$493,A35,ProductList!$V$4:$V$493) -> 0 | M35: =SUMIF(ProductList!$F$4:$F$493,A35,ProductList!$K$4:$K$493) -> 0 | N35: KG | O35: =IF(D35="SCL",100,AZ35) -> 80 | P35: =IF((K35*Y35)>(L35*AH35),(K35*Y35),(L35*AH35)) -> 0 | Q35: =IF((K35*Z35)>(L35*AI35),(K35*Z35),(L35*AI35)) -> 0 | R35: =IF(C35="SG", IF(((K35*1.1+P35+Q35+T35+V35)*AA35)>(L35*AJ35), (K35*1.1+P35+Q35+T35+V35)*AA35, L35*AJ35), IF(((K35*1.1+P35+Q35+S35+U35)*AA35)>(L35*AJ35), (K35*1.1+P35+Q35+S35+U35)*AA35, L35*AJ35) ) -> 0 | S35: =IF((K35*AB35)>(L35*AK35),(K35*AB35),(L35*AK35)) -> 0 | T35: =IF((K35*AC35)>(L35*AL35),(K35*AC35),(L35*AL35)) -> 0 | U35: =IF((K35*AD35)>(L35*AM35),(K35*AD35),(L35*AM35)) -> 0 | V35: =IF((K35*AE35)>(L35*AN35),(K35*AE35),(L35*AN35)) -> 0 | W35: =IF((K35*AF35)>(L35*AO35),(K35*AF35),(L35*AO35)) -> 0 | X35: =IF((((K35)*1.1+P35+Q35+S35+T35+U35+V35)*AG35)>(L35*AP35),(((K35)*1.1+P35+Q35+S35+T35+U35+V35)*AG35),(L35*AP35)) -> 0 | Z35: 0.2 | AA35: 0.18 | AB35: 0.1 | AD35: 0.45 | AG35: 0.025 | AI35: 100 | AM35: 260 | AZ35: =AZ34 -> 80
A36: 19019099 | B36: HEALTH DRINK | D36: NORM | E36: =IF(D36="SCL",G36,H36) -> 0 | H36: =ROUND(I36,0) -> 0 | I36: =IF(AND(L36<>"",L36<>0),ROUND(J36/L36,0),0) -> 0 | J36: =IF(C36="SG",ROUND((P36+Q36+R36+T36+V36+W36+X36),0),ROUND((P36+Q36+R36+S36+U36+W36+X36),0)) -> 0 | K36: =SUMIF(ProductList!$F$4:$F$493,A36,ProductList!$BA$4:$BA$493) -> 0 | L36: =SUMIF(ProductList!$F$4:$F$493,A36,ProductList!$V$4:$V$493) -> 0 | M36: =SUMIF(ProductList!$F$4:$F$493,A36,ProductList!$K$4:$K$493) -> 0 | N36: KG | O36: =IF(D36="SCL",100,AZ36) -> 80 | P36: =IF((K36*Y36)>(L36*AH36),(K36*Y36),(L36*AH36)) -> 0 | Q36: =IF((K36*Z36)>(L36*AI36),(K36*Z36),(L36*AI36)) -> 0 | R36: =IF(C36="SG", IF(((K36*1.1+P36+Q36+T36+V36)*AA36)>(L36*AJ36), (K36*1.1+P36+Q36+T36+V36)*AA36, L36*AJ36), IF(((K36*1.1+P36+Q36+S36+U36)*AA36)>(L36*AJ36), (K36*1.1+P36+Q36+S36+U36)*AA36, L36*AJ36) ) -> 0 | S36: =IF((K36*AB36)>(L36*AK36),(K36*AB36),(L36*AK36)) -> 0 | T36: =IF((K36*AC36)>(L36*AL36),(K36*AC36),(L36*AL36)) -> 0 | U36: =IF((K36*AD36)>(L36*AM36),(K36*AD36),(L36*AM36)) -> 0 | V36: =IF((K36*AE36)>(L36*AN36),(K36*AE36),(L36*AN36)) -> 0 | W36: =IF((K36*AF36)>(L36*AO36),(K36*AF36),(L36*AO36)) -> 0 | X36: =IF((((K36)*1.1+P36+Q36+S36+T36+U36+V36)*AG36)>(L36*AP36),(((K36)*1.1+P36+Q36+S36+T36+U36+V36)*AG36),(L36*AP36)) -> 0 | AA36: 0.18 | AB36: 0.1 | AC36: 0.06 | AD36: 0.05 | AE36: 0.04 | AG36: 0.025 | AZ36: =AZ35 -> 80
A37: 19021900 | B37: VERMICILLI | E37: =IF(D37="SCL",G37,H37) -> 0 | F37: S | H37: =ROUND(I37,0) -> 0 | I37: =IF(AND(L37<>"",L37<>0),ROUND(J37/L37,0),0) -> 0 | J37: =IF(C37="SG",ROUND((P37+Q37+R37+T37+V37+W37+X37),0),ROUND((P37+Q37+R37+S37+U37+W37+X37),0)) -> 0 | K37: =SUMIF(ProductList!$F$4:$F$493,A37,ProductList!$BA$4:$BA$493) -> 0 | L37: =SUMIF(ProductList!$F$4:$F$493,A37,ProductList!$V$4:$V$493) -> 0 | M37: =SUMIF(ProductList!$F$4:$F$493,A37,ProductList!$K$4:$K$493) -> 0 | N37: KG | O37: =IF(D37="SCL",100,AZ37) -> 80 | P37: =IF((K37*Y37)>(L37*AH37),(K37*Y37),(L37*AH37)) -> 0 | Q37: =IF((K37*Z37)>(L37*AI37),(K37*Z37),(L37*AI37)) -> 0 | R37: =IF(C37="SG", IF(((K37*1.1+P37+Q37+T37+V37)*AA37)>(L37*AJ37), (K37*1.1+P37+Q37+T37+V37)*AA37, L37*AJ37), IF(((K37*1.1+P37+Q37+S37+U37)*AA37)>(L37*AJ37), (K37*1.1+P37+Q37+S37+U37)*AA37, L37*AJ37) ) -> 0 | S37: =IF((K37*AB37)>(L37*AK37),(K37*AB37),(L37*AK37)) -> 0 | T37: =IF((K37*AC37)>(L37*AL37),(K37*AC37),(L37*AL37)) -> 0 | U37: =IF((K37*AD37)>(L37*AM37),(K37*AD37),(L37*AM37)) -> 0 | V37: =IF((K37*AE37)>(L37*AN37),(K37*AE37),(L37*AN37)) -> 0 | W37: =IF((K37*AF37)>(L37*AO37),(K37*AF37),(L37*AO37)) -> 0 | X37: =IF((((K37)*1.1+P37+Q37+S37+T37+U37+V37)*AG37)>(L37*AP37),(((K37)*1.1+P37+Q37+S37+T37+U37+V37)*AG37),(L37*AP37)) -> 0 | Z37: 0.2 | AA37: 0.18 | AB37: 0.1 | AC37: 0.06 | AD37: 0.3 | AE37: 0.24 | AG37: 0.025 | AI37: 160 | AM37: 140 | AN37: 64 | AZ37: =AZ36 -> 80
A38: 19041000 | B38: CEREALS OR CEREAL PRODUCTS | D38: NORM | E38: =IF(D38="SCL",G38,H38) -> 0 | H38: =ROUND(I38,0) -> 0 | I38: =IF(AND(L38<>"",L38<>0),ROUND(J38/L38,0),0) -> 0 | J38: =IF(C38="SG",ROUND((P38+Q38+R38+T38+V38+W38+X38),0),ROUND((P38+Q38+R38+S38+U38+W38+X38),0)) -> 0 | K38: =SUMIF(ProductList!$F$4:$F$493,A38,ProductList!$BA$4:$BA$493) -> 0 | L38: =SUMIF(ProductList!$F$4:$F$493,A38,ProductList!$V$4:$V$493) -> 0 | M38: =SUMIF(ProductList!$F$4:$F$493,A38,ProductList!$K$4:$K$493) -> 0 | N38: KG | O38: =IF(D38="SCL",100,AZ38) -> 80 | P38: =IF((K38*Y38)>(L38*AH38),(K38*Y38),(L38*AH38)) -> 0 | Q38: =IF((K38*Z38)>(L38*AI38),(K38*Z38),(L38*AI38)) -> 0 | R38: =IF(C38="SG", IF(((K38*1.1+P38+Q38+T38+V38)*AA38)>(L38*AJ38), (K38*1.1+P38+Q38+T38+V38)*AA38, L38*AJ38), IF(((K38*1.1+P38+Q38+S38+U38)*AA38)>(L38*AJ38), (K38*1.1+P38+Q38+S38+U38)*AA38, L38*AJ38) ) -> 0 | S38: =IF((K38*AB38)>(L38*AK38),(K38*AB38),(L38*AK38)) -> 0 | T38: =IF((K38*AC38)>(L38*AL38),(K38*AC38),(L38*AL38)) -> 0 | U38: =IF((K38*AD38)>(L38*AM38),(K38*AD38),(L38*AM38)) -> 0 | V38: =IF((K38*AE38)>(L38*AN38),(K38*AE38),(L38*AN38)) -> 0 | W38: =IF((K38*AF38)>(L38*AO38),(K38*AF38),(L38*AO38)) -> 0 | X38: =IF((((K38)*1.1+P38+Q38+S38+T38+U38+V38)*AG38)>(L38*AP38),(((K38)*1.1+P38+Q38+S38+T38+U38+V38)*AG38),(L38*AP38)) -> 0 | Z38: 0.2 | AA38: 0.18 | AB38: 0.1 | AC38: 0 | AD38: 0.3 | AG38: 0.025 | AI38: 230 | AM38: 140 | AZ38: =AZ37 -> 80
A39: 19049000 | B39: PREPARED FOOD PUFFED RICE | E39: =IF(D39="SCL",G39,H39) -> 0 | H39: =ROUND(I39,0) -> 0 | I39: =IF(AND(L39<>"",L39<>0),ROUND(J39/L39,0),0) -> 0 | J39: =IF(C39="SG",ROUND((P39+Q39+R39+T39+V39+W39+X39),0),ROUND((P39+Q39+R39+S39+U39+W39+X39),0)) -> 0 | K39: =SUMIF(ProductList!$F$4:$F$493,A39,ProductList!$BA$4:$BA$493) -> 0 | L39: =SUMIF(ProductList!$F$4:$F$493,A39,ProductList!$V$4:$V$493) -> 0 | M39: =SUMIF(ProductList!$F$4:$F$493,A39,ProductList!$K$4:$K$493) -> 0 | N39: KG | O39: =IF(D39="SCL",100,AZ39) -> 80 | P39: =IF((K39*Y39)>(L39*AH39),(K39*Y39),(L39*AH39)) -> 0 | Q39: =IF((K39*Z39)>(L39*AI39),(K39*Z39),(L39*AI39)) -> 0 | R39: =IF(C39="SG", IF(((K39*1.1+P39+Q39+T39+V39)*AA39)>(L39*AJ39), (K39*1.1+P39+Q39+T39+V39)*AA39, L39*AJ39), IF(((K39*1.1+P39+Q39+S39+U39)*AA39)>(L39*AJ39), (K39*1.1+P39+Q39+S39+U39)*AA39, L39*AJ39) ) -> 0 | S39: =IF((K39*AB39)>(L39*AK39),(K39*AB39),(L39*AK39)) -> 0 | T39: =IF((K39*AC39)>(L39*AL39),(K39*AC39),(L39*AL39)) -> 0 | U39: =IF((K39*AD39)>(L39*AM39),(K39*AD39),(L39*AM39)) -> 0 | V39: =IF((K39*AE39)>(L39*AN39),(K39*AE39),(L39*AN39)) -> 0 | W39: =IF((K39*AF39)>(L39*AO39),(K39*AF39),(L39*AO39)) -> 0 | X39: =IF((((K39)*1.1+P39+Q39+S39+T39+U39+V39)*AG39)>(L39*AP39),(((K39)*1.1+P39+Q39+S39+T39+U39+V39)*AG39),(L39*AP39)) -> 0 | Z39: 0.2 | AA39: 0.18 | AB39: 0.1 | AD39: 0.3 | AG39: 0.025 | AI39: 230 | AM39: 140 | AZ39: =AZ38 -> 80
A40: 19053100 | B40: SWEET BISCUITS | D40: NORM | E40: =IF(D40="SCL",G40,H40) -> 0 | H40: =ROUND(I40,0) -> 0 | I40: =IF(AND(L40<>"",L40<>0),ROUND(J40/L40,0),0) -> 0 | J40: =IF(C40="SG",ROUND((P40+Q40+R40+T40+V40+W40+X40),0),ROUND((P40+Q40+R40+S40+U40+W40+X40),0)) -> 0 | K40: =SUMIF(ProductList!$F$4:$F$493,A40,ProductList!$BA$4:$BA$493) -> 0 | L40: =SUMIF(ProductList!$F$4:$F$493,A40,ProductList!$V$4:$V$493) -> 0 | M40: =SUMIF(ProductList!$F$4:$F$493,A40,ProductList!$K$4:$K$493) -> 0 | N40: KG | O40: =IF(D40="SCL",100,AZ40) -> 80 | P40: =IF((K40*Y40)>(L40*AH40),(K40*Y40),(L40*AH40)) -> 0 | Q40: =IF((K40*Z40)>(L40*AI40),(K40*Z40),(L40*AI40)) -> 0 | R40: =IF(C40="SG", IF(((K40*1.1+P40+Q40+T40+V40)*AA40)>(L40*AJ40), (K40*1.1+P40+Q40+T40+V40)*AA40, L40*AJ40), IF(((K40*1.1+P40+Q40+S40+U40)*AA40)>(L40*AJ40), (K40*1.1+P40+Q40+S40+U40)*AA40, L40*AJ40) ) -> 0 | S40: =IF((K40*AB40)>(L40*AK40),(K40*AB40),(L40*AK40)) -> 0 | T40: =IF((K40*AC40)>(L40*AL40),(K40*AC40),(L40*AL40)) -> 0 | U40: =IF((K40*AD40)>(L40*AM40),(K40*AD40),(L40*AM40)) -> 0 | V40: =IF((K40*AE40)>(L40*AN40),(K40*AE40),(L40*AN40)) -> 0 | W40: =IF((K40*AF40)>(L40*AO40),(K40*AF40),(L40*AO40)) -> 0 | X40: =IF((((K40)*1.1+P40+Q40+S40+T40+U40+V40)*AG40)>(L40*AP40),(((K40)*1.1+P40+Q40+S40+T40+U40+V40)*AG40),(L40*AP40)) -> 0 | Z40: 0.2 | AA40: 0.18 | AB40: 0.1 | AD40: 0.35 | AG40: 0.025 | AI40: 160 | AW40: =35%*65% -> 0.2275 | AZ40: =AZ39 -> 80
...

Sheet SI
B2: 2026_6_2_NATRAJ
Q4: CUST ID | R4: GROUP
B5: DATE | C5: CAPITAL | D5: SHIPMENT | E5: DETAILS | F5: PURCHASE | G5: EXPENSES | H5: INVESTED | I5: SALES | J5: LOSSES | K5: TT ADJ | L5: GST CLAIM | M5: P/L | N5: P/L (%) | Q5: 1 | R5: NOODLES | T5: NOODLES
F6: =C21 -> 2574356 | G6: =C30 -> 2483298 | H6: =F6+G6 -> 5057654 | I6: =C33 -> 6113256 | J6: =C42 -> 135223 | K6: =C39 -> 135223 | L6: =C36 -> 128715 | M6: =I6-(H6+J6+K6)+L6 -> 913871 | N6: =ROUND(M6*100/(H6+J6+K6),2) -> 17.15 | Q6: 2 | R6: RICE | T6: HONEY
R7: GHEE | T7: GHEE
R8: COFFEE POWDER | T8: MUSTARD OIL
B9: LKR Conversion Rate | C9: 3.52 | F9: SETTLEMENT | G9: Settlement No | H9: 1 | I9: 2 | R9: PAPADS | T9: PAPADS
B10: $ Conversion Rate | C10: 95.19 | G10: Date | R10: TEA POWDER | T10: HEALTH DRINK
B11: Margin Config | C11: 15 | G11: Rate | R11: ASSORTED CURRY MASALA | T11: ASSORTED CURRY MASALA
B12: Invoice Margin | C12: 30 | G12: LKR | R12: ASSORTED MANIMARK SNACKS | T12: ASSORTED MANIMARK SNACKS
B13: Shipping Clearance Amount India (INR) | C13: 200000 | G13: INR | J13: =IF(AND(J12<>"",J11<>""),J12/J11,"") | K13: =IF(AND(K12<>"",K11<>""),K12/K11,"") | L13: =IF(AND(L12<>"",L11<>""),L12/L11,"") | M13: =IF(AND(M12<>"",M11<>""),M12/M11,"") | N13: =IF(AND(N12<>"",N11<>""),N12/N11,"") | R13: ASSORTED HALDIRAMS SNACKS | T13: ASSORTED HALDIRAMS SNACKS
B14: Shipping Clearance Amount Srilanka (LKR) | C14: 2000000 | G14: FROM | R14: MILLETS | T14: MILLETS
R15: ASSORTED PICKLES | T15: ASSORTED PICKLES
B16: PARTICULARS | C16: TOTAL | G16: 1 | K16: 2 | R16: HEALTH MIXES | T16: HEALTH MIXES
C17: INR | E17: LKR | G17: INR | I17: LKR | K17: INR | M17: LKR | R17: ASSORTED COFFEE POWDER | T17: ASSORTED COFFEE POWDER
C18: PREDICTED | D18: ACTUAL | E18: PREDICTED | F18: ACTUAL | G18: PREDICTED | H18: ACTUAL | I18: PREDICTED | J18: ACTUAL | K18: PREDICTED | L18: ACTUAL | M18: PREDICTED | N18: ACTUAL | R18: ASSORTED PAYASAM MIXES | T18: ASSORTED CHILLI POWDER
B19: PURCHASE | C19: =SUM(G19+K19) -> 2574356 | D19: =SUM(H19+L19) -> 2574356 | E19: =ROUND(C19*$C$9,0) -> 9061733 | F19: =ROUND(D19*$C$9,0) -> 9061733 | G19: =SUMIF(ProductList!$C$5:$C$493,G16,ProductList!$AA$5:$AA$493) -> 2574356 | H19: =SUMIF(ProductList!$C$5:$C$493,G16,ProductList!$AA$5:$AA$493) -> 2574356 | I19: =ROUND(G19*$C$9,0) -> 9061733 | J19: =ROUND(H19*$C$9,0) -> 9061733 | K19: =SUMIF(ProductList!$C$5:$C$493,K16,ProductList!$AA$5:$AA$493) -> 0 | L19: =SUMIF(ProductList!$C$5:$C$493,K16,ProductList!$AA$5:$AA$493) -> 0 | M19: =ROUND(K19*$C$9,0) -> 0 | N19: =ROUND(L19*$C$9,0) -> 0 | R19: OATS | T19: FOOD COLOUR
B20: GST | C20: =SUM(G20+K20) -> 128715 | D20: =SUM(H20+L20) -> 128715 | E20: =ROUND(C20*$C$9,0) -> 453077 | F20: =ROUND(D20*$C$9,0) -> 453077 | G20: =ROUND(SUMIF(ProductList!$C$5:$C$493,G16,ProductList!$AB$5:$AB$493),0) -> 128715 | H20: =ROUND(SUMIF(ProductList!$C$5:$C$493,G16,ProductList!$AB$5:$AB$493),0) -> 128715 | I20: =ROUND(G20*$C$9,0) -> 453077 | J20: =ROUND(H20*$C$9,0) -> 453077 | K20: =ROUND(SUMIF(ProductList!$C$5:$C$493,K16,ProductList!$AB$5:$AB$493),0) -> 0 | L20: =ROUND(SUMIF(ProductList!$C$5:$C$493,K16,ProductList!$AB$5:$AB$493),0) -> 0 | M20: =ROUND(K20*$C$9,0) -> 0 | N20: =ROUND(L20*$C$9,0) -> 0
B21: (Leavning GST) Net Purchase | C21: =ROUND(C19,0) -> 2574356 | D21: =ROUND(D19,0) -> 2574356 | E21: =ROUND(E19,0) -> 9061733 | F21: =ROUND(F19,0) -> 9061733 | G21: =ROUND(G19,0) -> 2574356 | H21: =ROUND(H19,0) -> 2574356 | I21: =ROUND(I19,0) -> 9061733 | J21: =ROUND(J19,0) -> 9061733 | ... N21: =ROUND(N19,0) -> 0
B23: Shipping & Clearing Expenses India | C23: =C13 -> 200000 | D23: =C13 -> 200000 | E23: =C23*$C$9 -> 704000 | F23: =D23*$C$9 -> 704000 | G23: =C13 -> 200000 | H23: =C13 -> 200000 | I23: =ROUND(SUMIF(ProductList!$C$5:$C$493,G$16,ProductList!$AE$5:$AE$493),0) -> 703998 | J23: =ROUND(SUMIF(ProductList!$C$5:$C$493,G$16,ProductList!$AE$5:$AE$493),0) -> 703998 | M23: =ROUND(SUMIF(ProductList!$C$5:$C$493,K$16,ProductList!$AE$5:$AE$493),0) -> 0
B24: CIF Value (100%) | C24: =C23+C21 -> 2774356 | D24: =D23+D21 -> 2774356 | E24: =E23+E21 -> 9765733 | F24: =F23+F21 -> 9765733 | G24: =G23+G21 -> 2774356 | H24: =H23+H21 -> 2774356 | I24: =I23+I21 -> 9765731 | J24: =J23+J21 -> 9765731 | ... N24: =N23+N21 -> 0
B25: INVOICE VALUE in USD | C25: =SUMIF(ProductList!$C$5:$C$493,G16,ProductList!$BB$5:$BB$493) -> 24771.61
B27: SriLanka Duty | C27: =SUM(G27+K27) -> 1715116 | D27: =SUM(H27+L27) -> 1676136 | E27: =SUM(I27+M27) -> 6037207 | F27: =SUM(J27+N27) -> 5900000 | G27: =ROUND(SUMIF(ProductList!$C$5:$C$493,G16,ProductList!$AP$5:$AP$493),0) -> 1715116 | H27: =ROUND(J27/$C$9,0) -> 1676136 | I27: =ROUND(SUMIF(ProductList!$C$5:$C$493,G16,ProductList!$AG$5:$AG$493),0) -> 6037207 | J27: 5900000 | K27: =ROUND(SUMIF(ProductList!$C$5:$C$493,K16,ProductList!$AP$5:$AP$493),0) -> 0 | L27: =ROUND(N27/$C$9,0) -> 0 | M27: =ROUND(SUMIF(ProductList!$C$5:$C$493,K16,ProductList!$AG$5:$AG$493),0) -> 0 | N27: 0
B28: Clearing Expenses | C28: =ROUND($C$14/$C$9,0) -> 568182 | D28: =SUM(H28+L28) -> 568182 | E28: =ROUND(C28*$C$9,0) -> 2000001 | F28: =J28+N28 -> 2000000 | G28: =ROUND(SUMIF(ProductList!$C$5:$C$493,G16,ProductList!$AR$5:$AR$493),0) -> 568181 | H28: =ROUND(J28/$C$9,0) -> 568182 | I28: =ROUND(SUMIF(ProductList!$C$5:$C$493,G16,ProductList!$AI$5:$AI$493),0) -> 1999998 | J28: 2000000 | L28: =ROUND(N28/$C$9,0) -> 0
B29: Expenses Colombo (Duty + clearnce) | C29: =SUM(C27:C28) -> 2283298 | D29: =SUM(H29+L29) -> 2244318 | E29: =SUM(I29+M29) -> 8037205 | F29: =SUM(J29+N29) -> 7900000 | G29: =SUM(G27:G28) -> 2283297 | H29: =ROUND(J29/$C$9,0) -> 2244318 | I29: =SUM(I27:I28) -> 8037205 | J29: =SUM(J27:J28) -> 7900000 | K29: =SUM(K27:K28) -> 0 | L29: =ROUND(N29/$C$9,0) -> 0 | M29: =SUM(M27:M28) -> 0 | N29: =SUM(N27:N28) -> 0
B30: Expenses Total (India + Colombo) | C30: =C29+C23 -> 2483298 | D30: =SUM(H30+L30) -> 2444318 | E30: =E23+E28 -> 2704001 | F30: =SUM(J30+N30) -> 8603998 | G30: =G29+G23 -> 2483297 | H30: =ROUND(J30/$C$9,0) -> 2444318 | I30: =I29+I23 -> 8741203 | J30: =J29+J23 -> 8603998 | K30: =K29+K23 -> 0 | L30: =ROUND(N30/$C$9,0) -> 0 | M30: =M29+M23 -> 0 | N30: =N29+N23 -> 0
B32: TOTAL INVESTMENT (Net Purchase + ExpensesTotal) | C32: =C21+C30 -> 5057654 | D32: =D21+D30 -> 5018674 | E32: =E21+E30 -> 11765734 | F32: =F21+F30 -> 17665731 | G32: =G21+G30 -> 5057653 | H32: =H21+H30 -> 5018674 | I32: =I21+I30 -> 17802936 | J32: =J21+J30 -> 17665731 | ... N32: =N21+N30 -> 0
